{
  "version": 8,
  "blockIdVersion": 11,
  "anchorX": 0,
  "anchorY": 0,
  "anchorZ": 0,
  "blocks": [
    {
      "x": -57,
      "y": 0,
      "z": -23,
      "name": "Cloth_Block_Wool_Yellow"
    },
    {
      "x": -55,
      "y": 12,
      "z": -4,
      "name": "Pipe_Shell"
    },
    {
      "x": -55,
      "y": 13,
      "z": -4,
      "name": "Pipe_Shell"
    },
    {
      "x": -55,
      "y": 14,
      "z": -4,
      "name": "Pipe_Shell"
    },
    {
      "x": -55,
      "y": 15,
      "z": -4,
      "name": "Pipe_Shell"
    },
    {
      "x": -55,
      "y": 16,
      "z": -4,
      "name": "Pipe_Shell"
    },
    {
      "x": -55,
      "y": 12,
      "z": -3,
      "name": "Pipe_Shell"
    },
    {
      "x": -55,
      "y": 13,
      "z": -3,
      "name": "Pipe_Shell"
    },
    {
      "x": -55,
      "y": 14,
      "z": -3,
      "name": "Pipe_Shell"
    },
    {
      "x": -55,
      "y": 15,
      "z": -3,
      "name": "Pipe_Shell"
    },
    {
      "x": -55,
      "y": 16,
      "z": -3,
      "name": "Pipe_Shell"
    },
    {
      "x": -55,
      "y": 12,
      "z": -2,
      "name": "Pipe_Shell"
    },
    {
      "x": -55,
      "y": 13,
      "z": -2,
      "name": "Pipe_Shell"
    },
    {
      "x": -55,
      "y": 14,
      "z": -2,
      "name": "Pipe_Shell"
    },
    {
      "x": -55,
      "y": 15,
      "z": -2,
      "name": "Pipe_Shell"
    },
    {
      "x": -55,
      "y": 16,
      "z": -2,
      "name": "Pipe_Shell"
    },
    {
      "x": -55,
      "y": 12,
      "z": -1,
      "name": "Pipe_Shell"
    },
    {
      "x": -55,
      "y": 13,
      "z": -1,
      "name": "Pipe_Shell"
    },
    {
      "x": -55,
      "y": 14,
      "z": -1,
      "name": "Pipe_Shell"
    },
    {
      "x": -55,
      "y": 15,
      "z": -1,
      "name": "Pipe_Shell"
    },
    {
      "x": -55,
      "y": 16,
      "z": -1,
      "name": "Pipe_Shell"
    },
    {
      "x": -55,
      "y": 12,
      "z": 0,
      "name": "Pipe_Shell"
    },
    {
      "x": -55,
      "y": 13,
      "z": 0,
      "name": "Pipe_Shell"
    },
    {
      "x": -55,
      "y": 14,
      "z": 0,
      "name": "Pipe_Shell"
    },
    {
      "x": -55,
      "y": 15,
      "z": 0,
      "name": "Pipe_Shell"
    },
    {
      "x": -55,
      "y": 16,
      "z": 0,
      "name": "Pipe_Shell"
    },
    {
      "x": -55,
      "y": 12,
      "z": 1,
      "name": "Pipe_Shell"
    },
    {
      "x": -55,
      "y": 13,
      "z": 1,
      "name": "Pipe_Shell"
    },
    {
      "x": -55,
      "y": 14,
      "z": 1,
      "name": "Pipe_Shell"
    },
    {
      "x": -55,
      "y": 15,
      "z": 1,
      "name": "Pipe_Shell"
    },
    {
      "x": -55,
      "y": 16,
      "z": 1,
      "name": "Pipe_Shell"
    },
    {
      "x": -55,
      "y": 12,
      "z": 2,
      "name": "Pipe_Shell"
    },
    {
      "x": -55,
      "y": 13,
      "z": 2,
      "name": "Pipe_Shell"
    },
    {
      "x": -55,
      "y": 14,
      "z": 2,
      "name": "Pipe_Shell"
    },
    {
      "x": -55,
      "y": 15,
      "z": 2,
      "name": "Pipe_Shell"
    },
    {
      "x": -55,
      "y": 16,
      "z": 2,
      "name": "Pipe_Shell"
    },
    {
      "x": -55,
      "y": 12,
      "z": 3,
      "name": "Pipe_Shell"
    },
    {
      "x": -55,
      "y": 13,
      "z": 3,
      "name": "Pipe_Shell"
    },
    {
      "x": -55,
      "y": 14,
      "z": 3,
      "name": "Pipe_Shell"
    },
    {
      "x": -55,
      "y": 15,
      "z": 3,
      "name": "Pipe_Shell"
    },
    {
      "x": -55,
      "y": 16,
      "z": 3,
      "name": "Pipe_Shell"
    },
    {
      "x": -55,
      "y": 12,
      "z": 4,
      "name": "Pipe_Shell"
    },
    {
      "x": -55,
      "y": 13,
      "z": 4,
      "name": "Pipe_Shell"
    },
    {
      "x": -55,
      "y": 14,
      "z": 4,
      "name": "Pipe_Shell"
    },
    {
      "x": -55,
      "y": 15,
      "z": 4,
      "name": "Pipe_Shell"
    },
    {
      "x": -55,
      "y": 16,
      "z": 4,
      "name": "Pipe_Shell"
    },
    {
      "x": -54,
      "y": 12,
      "z": -4,
      "name": "Pipe_Shell"
    },
    {
      "x": -54,
      "y": 13,
      "z": -4,
      "name": "Pipe_Shell"
    },
    {
      "x": -54,
      "y": 14,
      "z": -4,
      "name": "Pipe_Shell"
    },
    {
      "x": -54,
      "y": 15,
      "z": -4,
      "name": "Pipe_Shell"
    },
    {
      "x": -54,
      "y": 16,
      "z": -4,
      "name": "Pipe_Shell"
    },
    {
      "x": -54,
      "y": 12,
      "z": -3,
      "name": "Pipe_Shell"
    },
    {
      "x": -54,
      "y": 16,
      "z": -3,
      "name": "Pipe_Shell"
    },
    {
      "x": -54,
      "y": 12,
      "z": -2,
      "name": "Pipe_Shell"
    },
    {
      "x": -54,
      "y": 16,
      "z": -2,
      "name": "Pipe_Shell"
    },
    {
      "x": -54,
      "y": 12,
      "z": -1,
      "name": "Pipe_Shell"
    },
    {
      "x": -54,
      "y": 16,
      "z": -1,
      "name": "Pipe_Shell"
    },
    {
      "x": -54,
      "y": 12,
      "z": 0,
      "name": "Pipe_Shell"
    },
    {
      "x": -54,
      "y": 16,
      "z": 0,
      "name": "Pipe_Shell"
    },
    {
      "x": -54,
      "y": 12,
      "z": 1,
      "name": "Pipe_Shell"
    },
    {
      "x": -54,
      "y": 16,
      "z": 1,
      "name": "Pipe_Shell"
    },
    {
      "x": -54,
      "y": 12,
      "z": 2,
      "name": "Pipe_Shell"
    },
    {
      "x": -54,
      "y": 16,
      "z": 2,
      "name": "Pipe_Shell"
    },
    {
      "x": -54,
      "y": 12,
      "z": 3,
      "name": "Pipe_Shell"
    },
    {
      "x": -54,
      "y": 16,
      "z": 3,
      "name": "Pipe_Shell"
    },
    {
      "x": -54,
      "y": 12,
      "z": 4,
      "name": "Pipe_Shell"
    },
    {
      "x": -54,
      "y": 13,
      "z": 4,
      "name": "Pipe_Shell"
    },
    {
      "x": -54,
      "y": 14,
      "z": 4,
      "name": "Pipe_Shell"
    },
    {
      "x": -54,
      "y": 15,
      "z": 4,
      "name": "Pipe_Shell"
    },
    {
      "x": -54,
      "y": 16,
      "z": 4,
      "name": "Pipe_Shell"
    },
    {
      "x": -53,
      "y": 12,
      "z": -4,
      "name": "Pipe_Shell"
    },
    {
      "x": -53,
      "y": 13,
      "z": -4,
      "name": "Pipe_Shell"
    },
    {
      "x": -53,
      "y": 14,
      "z": -4,
      "name": "Pipe_Shell"
    },
    {
      "x": -53,
      "y": 15,
      "z": -4,
      "name": "Pipe_Shell"
    },
    {
      "x": -53,
      "y": 16,
      "z": -4,
      "name": "Pipe_Shell"
    },
    {
      "x": -53,
      "y": 12,
      "z": -3,
      "name": "Pipe_Shell"
    },
    {
      "x": -53,
      "y": 16,
      "z": -3,
      "name": "Pipe_Shell"
    },
    {
      "x": -53,
      "y": 12,
      "z": -2,
      "name": "Pipe_Shell"
    },
    {
      "x": -53,
      "y": 16,
      "z": -2,
      "name": "Pipe_Shell"
    },
    {
      "x": -53,
      "y": 12,
      "z": -1,
      "name": "Pipe_Shell"
    },
    {
      "x": -53,
      "y": 16,
      "z": -1,
      "name": "Pipe_Shell"
    },
    {
      "x": -53,
      "y": 12,
      "z": 0,
      "name": "Pipe_Shell"
    },
    {
      "x": -53,
      "y": 16,
      "z": 0,
      "name": "Pipe_Shell"
    },
    {
      "x": -53,
      "y": 12,
      "z": 1,
      "name": "Pipe_Shell"
    },
    {
      "x": -53,
      "y": 16,
      "z": 1,
      "name": "Pipe_Shell"
    },
    {
      "x": -53,
      "y": 12,
      "z": 2,
      "name": "Pipe_Shell"
    },
    {
      "x": -53,
      "y": 16,
      "z": 2,
      "name": "Pipe_Shell"
    },
    {
      "x": -53,
      "y": 12,
      "z": 3,
      "name": "Pipe_Shell"
    },
    {
      "x": -53,
      "y": 16,
      "z": 3,
      "name": "Pipe_Shell"
    },
    {
      "x": -53,
      "y": 12,
      "z": 4,
      "name": "Pipe_Shell"
    },
    {
      "x": -53,
      "y": 13,
      "z": 4,
      "name": "Pipe_Shell"
    },
    {
      "x": -53,
      "y": 14,
      "z": 4,
      "name": "Pipe_Shell"
    },
    {
      "x": -53,
      "y": 15,
      "z": 4,
      "name": "Pipe_Shell"
    },
    {
      "x": -53,
      "y": 16,
      "z": 4,
      "name": "Pipe_Shell"
    },
    {
      "x": -52,
      "y": 12,
      "z": -4,
      "name": "Pipe_Shell"
    },
    {
      "x": -52,
      "y": 13,
      "z": -4,
      "name": "Rock_Crystal_Red_Block"
    },
    {
      "x": -52,
      "y": 14,
      "z": -4,
      "name": "Rock_Crystal_Red_Block"
    },
    {
      "x": -52,
      "y": 15,
      "z": -4,
      "name": "Rock_Crystal_Red_Block"
    },
    {
      "x": -52,
      "y": 16,
      "z": -4,
      "name": "Pipe_Shell"
    },
    {
      "x": -52,
      "y": 12,
      "z": -3,
      "name": "Pipe_Shell"
    },
    {
      "x": -52,
      "y": 16,
      "z": -3,
      "name": "Pipe_Shell"
    },
    {
      "x": -52,
      "y": 12,
      "z": -2,
      "name": "Pipe_Shell"
    },
    {
      "x": -52,
      "y": 16,
      "z": -2,
      "name": "Pipe_Shell"
    },
    {
      "x": -52,
      "y": 12,
      "z": -1,
      "name": "Pipe_Shell"
    },
    {
      "x": -52,
      "y": 16,
      "z": -1,
      "name": "Pipe_Shell"
    },
    {
      "x": -52,
      "y": 12,
      "z": 0,
      "name": "Pipe_Shell"
    },
    {
      "x": -52,
      "y": 16,
      "z": 0,
      "name": "Pipe_Shell"
    },
    {
      "x": -52,
      "y": 12,
      "z": 1,
      "name": "Pipe_Shell"
    },
    {
      "x": -52,
      "y": 16,
      "z": 1,
      "name": "Pipe_Shell"
    },
    {
      "x": -52,
      "y": 12,
      "z": 2,
      "name": "Pipe_Shell"
    },
    {
      "x": -52,
      "y": 16,
      "z": 2,
      "name": "Pipe_Shell"
    },
    {
      "x": -52,
      "y": 12,
      "z": 3,
      "name": "Pipe_Shell"
    },
    {
      "x": -52,
      "y": 16,
      "z": 3,
      "name": "Pipe_Shell"
    },
    {
      "x": -52,
      "y": 12,
      "z": 4,
      "name": "Pipe_Shell"
    },
    {
      "x": -52,
      "y": 13,
      "z": 4,
      "name": "Pipe_Shell"
    },
    {
      "x": -52,
      "y": 14,
      "z": 4,
      "name": "Pipe_Shell"
    },
    {
      "x": -52,
      "y": 15,
      "z": 4,
      "name": "Pipe_Shell"
    },
    {
      "x": -52,
      "y": 16,
      "z": 4,
      "name": "Pipe_Shell"
    },
    {
      "x": -51,
      "y": 12,
      "z": -4,
      "name": "Pipe_Shell"
    },
    {
      "x": -51,
      "y": 13,
      "z": -4,
      "name": "Pipe_Shell"
    },
    {
      "x": -51,
      "y": 14,
      "z": -4,
      "name": "Pipe_Shell"
    },
    {
      "x": -51,
      "y": 15,
      "z": -4,
      "name": "Pipe_Shell"
    },
    {
      "x": -51,
      "y": 16,
      "z": -4,
      "name": "Pipe_Shell"
    },
    {
      "x": -51,
      "y": 12,
      "z": -3,
      "name": "Pipe_Shell"
    },
    {
      "x": -51,
      "y": 13,
      "z": -3,
      "name": "Pipe_Shell"
    },
    {
      "x": -51,
      "y": 14,
      "z": -3,
      "name": "Pipe_Shell"
    },
    {
      "x": -51,
      "y": 15,
      "z": -3,
      "name": "Pipe_Shell"
    },
    {
      "x": -51,
      "y": 16,
      "z": -3,
      "name": "Pipe_Shell"
    },
    {
      "x": -51,
      "y": 12,
      "z": -2,
      "name": "Pipe_Shell"
    },
    {
      "x": -51,
      "y": 13,
      "z": -2,
      "name": "Pipe_Shell"
    },
    {
      "x": -51,
      "y": 14,
      "z": -2,
      "name": "Pipe_Shell"
    },
    {
      "x": -51,
      "y": 15,
      "z": -2,
      "name": "Pipe_Shell"
    },
    {
      "x": -51,
      "y": 16,
      "z": -2,
      "name": "Pipe_Shell"
    },
    {
      "x": -51,
      "y": 12,
      "z": -1,
      "name": "Pipe_Shell"
    },
    {
      "x": -51,
      "y": 13,
      "z": -1,
      "name": "Pipe_Shell"
    },
    {
      "x": -51,
      "y": 14,
      "z": -1,
      "name": "Pipe_Shell"
    },
    {
      "x": -51,
      "y": 15,
      "z": -1,
      "name": "Pipe_Shell"
    },
    {
      "x": -51,
      "y": 16,
      "z": -1,
      "name": "Pipe_Shell"
    },
    {
      "x": -51,
      "y": 12,
      "z": 0,
      "name": "Pipe_Shell"
    },
    {
      "x": -51,
      "y": 13,
      "z": 0,
      "name": "Pipe_Shell"
    },
    {
      "x": -51,
      "y": 14,
      "z": 0,
      "name": "Pipe_Shell"
    },
    {
      "x": -51,
      "y": 15,
      "z": 0,
      "name": "Pipe_Shell"
    },
    {
      "x": -51,
      "y": 16,
      "z": 0,
      "name": "Pipe_Shell"
    },
    {
      "x": -51,
      "y": 12,
      "z": 1,
      "name": "Pipe_Shell"
    },
    {
      "x": -51,
      "y": 16,
      "z": 1,
      "name": "Pipe_Shell"
    },
    {
      "x": -51,
      "y": 12,
      "z": 2,
      "name": "Pipe_Shell"
    },
    {
      "x": -51,
      "y": 16,
      "z": 2,
      "name": "Pipe_Shell"
    },
    {
      "x": -51,
      "y": 12,
      "z": 3,
      "name": "Pipe_Shell"
    },
    {
      "x": -51,
      "y": 16,
      "z": 3,
      "name": "Pipe_Shell"
    },
    {
      "x": -51,
      "y": 12,
      "z": 4,
      "name": "Pipe_Shell"
    },
    {
      "x": -51,
      "y": 13,
      "z": 4,
      "name": "Pipe_Shell"
    },
    {
      "x": -51,
      "y": 14,
      "z": 4,
      "name": "Pipe_Shell"
    },
    {
      "x": -51,
      "y": 15,
      "z": 4,
      "name": "Pipe_Shell"
    },
    {
      "x": -51,
      "y": 16,
      "z": 4,
      "name": "Pipe_Shell"
    },
    {
      "x": -50,
      "y": 12,
      "z": 0,
      "name": "Pipe_Shell"
    },
    {
      "x": -50,
      "y": 13,
      "z": 0,
      "name": "Pipe_Shell"
    },
    {
      "x": -50,
      "y": 14,
      "z": 0,
      "name": "Pipe_Shell"
    },
    {
      "x": -50,
      "y": 15,
      "z": 0,
      "name": "Pipe_Shell"
    },
    {
      "x": -50,
      "y": 16,
      "z": 0,
      "name": "Pipe_Shell"
    },
    {
      "x": -50,
      "y": 12,
      "z": 1,
      "name": "Pipe_Shell"
    },
    {
      "x": -50,
      "y": 16,
      "z": 1,
      "name": "Pipe_Shell"
    },
    {
      "x": -50,
      "y": 12,
      "z": 2,
      "name": "Pipe_Shell"
    },
    {
      "x": -50,
      "y": 16,
      "z": 2,
      "name": "Pipe_Shell"
    },
    {
      "x": -50,
      "y": 12,
      "z": 3,
      "name": "Pipe_Shell"
    },
    {
      "x": -50,
      "y": 16,
      "z": 3,
      "name": "Pipe_Shell"
    },
    {
      "x": -50,
      "y": 12,
      "z": 4,
      "name": "Pipe_Shell"
    },
    {
      "x": -50,
      "y": 13,
      "z": 4,
      "name": "Pipe_Shell"
    },
    {
      "x": -50,
      "y": 14,
      "z": 4,
      "name": "Pipe_Shell"
    },
    {
      "x": -50,
      "y": 15,
      "z": 4,
      "name": "Pipe_Shell"
    },
    {
      "x": -50,
      "y": 16,
      "z": 4,
      "name": "Pipe_Shell"
    },
    {
      "x": -49,
      "y": 12,
      "z": 0,
      "name": "Pipe_Shell"
    },
    {
      "x": -49,
      "y": 13,
      "z": 0,
      "name": "Pipe_Shell"
    },
    {
      "x": -49,
      "y": 14,
      "z": 0,
      "name": "Pipe_Shell"
    },
    {
      "x": -49,
      "y": 15,
      "z": 0,
      "name": "Pipe_Shell"
    },
    {
      "x": -49,
      "y": 16,
      "z": 0,
      "name": "Pipe_Shell"
    },
    {
      "x": -49,
      "y": 12,
      "z": 1,
      "name": "Pipe_Shell"
    },
    {
      "x": -49,
      "y": 16,
      "z": 1,
      "name": "Pipe_Shell"
    },
    {
      "x": -49,
      "y": 12,
      "z": 2,
      "name": "Pipe_Shell"
    },
    {
      "x": -49,
      "y": 16,
      "z": 2,
      "name": "Pipe_Shell"
    },
    {
      "x": -49,
      "y": 12,
      "z": 3,
      "name": "Pipe_Shell"
    },
    {
      "x": -49,
      "y": 16,
      "z": 3,
      "name": "Pipe_Shell"
    },
    {
      "x": -49,
      "y": 12,
      "z": 4,
      "name": "Pipe_Shell"
    },
    {
      "x": -49,
      "y": 13,
      "z": 4,
      "name": "Pipe_Shell"
    },
    {
      "x": -49,
      "y": 14,
      "z": 4,
      "name": "Pipe_Shell"
    },
    {
      "x": -49,
      "y": 15,
      "z": 4,
      "name": "Pipe_Shell"
    },
    {
      "x": -49,
      "y": 16,
      "z": 4,
      "name": "Pipe_Shell"
    },
    {
      "x": -48,
      "y": 12,
      "z": 0,
      "name": "Pipe_Shell"
    },
    {
      "x": -48,
      "y": 13,
      "z": 0,
      "name": "Pipe_Shell"
    },
    {
      "x": -48,
      "y": 14,
      "z": 0,
      "name": "Pipe_Shell"
    },
    {
      "x": -48,
      "y": 15,
      "z": 0,
      "name": "Pipe_Shell"
    },
    {
      "x": -48,
      "y": 16,
      "z": 0,
      "name": "Pipe_Shell"
    },
    {
      "x": -48,
      "y": 12,
      "z": 1,
      "name": "Pipe_Shell"
    },
    {
      "x": -48,
      "y": 16,
      "z": 1,
      "name": "Pipe_Shell"
    },
    {
      "x": -48,
      "y": 12,
      "z": 2,
      "name": "Pipe_Shell"
    },
    {
      "x": -48,
      "y": 16,
      "z": 2,
      "name": "Pipe_Shell"
    },
    {
      "x": -48,
      "y": 12,
      "z": 3,
      "name": "Pipe_Shell"
    },
    {
      "x": -48,
      "y": 16,
      "z": 3,
      "name": "Pipe_Shell"
    },
    {
      "x": -48,
      "y": 12,
      "z": 4,
      "name": "Pipe_Shell"
    },
    {
      "x": -48,
      "y": 13,
      "z": 4,
      "name": "Pipe_Shell"
    },
    {
      "x": -48,
      "y": 14,
      "z": 4,
      "name": "Pipe_Shell"
    },
    {
      "x": -48,
      "y": 15,
      "z": 4,
      "name": "Pipe_Shell"
    },
    {
      "x": -48,
      "y": 16,
      "z": 4,
      "name": "Pipe_Shell"
    },
    {
      "x": -47,
      "y": 12,
      "z": 0,
      "name": "Pipe_Shell"
    },
    {
      "x": -47,
      "y": 13,
      "z": 0,
      "name": "Pipe_Shell"
    },
    {
      "x": -47,
      "y": 14,
      "z": 0,
      "name": "Pipe_Shell"
    },
    {
      "x": -47,
      "y": 15,
      "z": 0,
      "name": "Pipe_Shell"
    },
    {
      "x": -47,
      "y": 16,
      "z": 0,
      "name": "Pipe_Shell"
    },
    {
      "x": -47,
      "y": 12,
      "z": 1,
      "name": "Pipe_Shell"
    },
    {
      "x": -47,
      "y": 14,
      "z": 1,
      "name": "Deco_Iron_Bars",
      "rotation": 1
    },
    {
      "x": -47,
      "y": 15,
      "z": 1,
      "name": "Deco_Iron_Bars",
      "rotation": 1
    },
    {
      "x": -47,
      "y": 16,
      "z": 1,
      "name": "Pipe_Shell"
    },
    {
      "x": -47,
      "y": 12,
      "z": 2,
      "name": "Pipe_Shell"
    },
    {
      "x": -47,
      "y": 14,
      "z": 2,
      "name": "Deco_Iron_Bars",
      "rotation": 1
    },
    {
      "x": -47,
      "y": 15,
      "z": 2,
      "name": "Deco_Iron_Bars",
      "rotation": 1
    },
    {
      "x": -47,
      "y": 16,
      "z": 2,
      "name": "Pipe_Shell"
    },
    {
      "x": -47,
      "y": 12,
      "z": 3,
      "name": "Pipe_Shell"
    },
    {
      "x": -47,
      "y": 14,
      "z": 3,
      "name": "Deco_Iron_Bars",
      "rotation": 1
    },
    {
      "x": -47,
      "y": 15,
      "z": 3,
      "name": "Deco_Iron_Bars",
      "rotation": 1
    },
    {
      "x": -47,
      "y": 16,
      "z": 3,
      "name": "Pipe_Shell"
    },
    {
      "x": -47,
      "y": 12,
      "z": 4,
      "name": "Pipe_Shell"
    },
    {
      "x": -47,
      "y": 13,
      "z": 4,
      "name": "Pipe_Shell"
    },
    {
      "x": -47,
      "y": 14,
      "z": 4,
      "name": "Pipe_Shell"
    },
    {
      "x": -47,
      "y": 15,
      "z": 4,
      "name": "Pipe_Shell"
    },
    {
      "x": -47,
      "y": 16,
      "z": 4,
      "name": "Pipe_Shell"
    },
    {
      "x": -46,
      "y": 0,
      "z": -10,
      "name": "Cloth_Block_Wool_Blue"
    },
    {
      "x": -46,
      "y": 1,
      "z": -10,
      "name": "Cloth_Block_Wool_Blue"
    },
    {
      "x": -46,
      "y": 2,
      "z": -10,
      "name": "Cloth_Block_Wool_Blue"
    },
    {
      "x": -46,
      "y": 3,
      "z": -10,
      "name": "Cloth_Block_Wool_Blue"
    },
    {
      "x": -46,
      "y": 4,
      "z": -10,
      "name": "Cloth_Block_Wool_Blue"
    },
    {
      "x": -46,
      "y": 5,
      "z": -10,
      "name": "Cloth_Block_Wool_Blue"
    },
    {
      "x": -46,
      "y": 6,
      "z": -10,
      "name": "Cloth_Block_Wool_Blue"
    },
    {
      "x": -46,
      "y": 7,
      "z": -10,
      "name": "Cloth_Block_Wool_Blue"
    },
    {
      "x": -46,
      "y": 8,
      "z": -10,
      "name": "Cloth_Block_Wool_Blue"
    },
    {
      "x": -46,
      "y": 9,
      "z": -10,
      "name": "Cloth_Block_Wool_Blue"
    },
    {
      "x": -46,
      "y": 10,
      "z": -10,
      "name": "Cloth_Block_Wool_Blue"
    },
    {
      "x": -46,
      "y": 11,
      "z": -10,
      "name": "Cloth_Block_Wool_Blue"
    },
    {
      "x": -46,
      "y": 12,
      "z": -10,
      "name": "Cloth_Block_Wool_Blue"
    },
    {
      "x": -46,
      "y": 13,
      "z": -10,
      "name": "Cloth_Block_Wool_Blue"
    },
    {
      "x": -46,
      "y": 14,
      "z": -10,
      "name": "Cloth_Block_Wool_Blue"
    },
    {
      "x": -46,
      "y": 15,
      "z": -10,
      "name": "Cloth_Block_Wool_Blue"
    },
    {
      "x": -46,
      "y": 16,
      "z": -10,
      "name": "Cloth_Block_Wool_Blue"
    },
    {
      "x": -46,
      "y": 0,
      "z": -9,
      "name": "Cloth_Block_Wool_Blue"
    },
    {
      "x": -46,
      "y": 6,
      "z": -9,
      "name": "Light_Tiles"
    },
    {
      "x": -46,
      "y": 7,
      "z": -9,
      "name": "Lightmetal_Base"
    },
    {
      "x": -46,
      "y": 8,
      "z": -9,
      "name": "Lightmetal_Vertical"
    },
    {
      "x": -46,
      "y": 9,
      "z": -9,
      "name": "Lightmetal_Top"
    },
    {
      "x": -46,
      "y": 10,
      "z": -9,
      "name": "Lightmetal_Base"
    },
    {
      "x": -46,
      "y": 11,
      "z": -9,
      "name": "Lightmetal_Vertical"
    },
    {
      "x": -46,
      "y": 12,
      "z": -9,
      "name": "Lightmetal_Vertical"
    },
    {
      "x": -46,
      "y": 13,
      "z": -9,
      "name": "Pipe_Shell"
    },
    {
      "x": -46,
      "y": 14,
      "z": -9,
      "name": "Pipe_Shell"
    },
    {
      "x": -46,
      "y": 15,
      "z": -9,
      "name": "Pipe_Shell"
    },
    {
      "x": -46,
      "y": 16,
      "z": -9,
      "name": "Cloth_Block_Wool_Blue"
    },
    {
      "x": -46,
      "y": 0,
      "z": -8,
      "name": "Cloth_Block_Wool_Blue"
    },
    {
      "x": -46,
      "y": 6,
      "z": -8,
      "name": "Light_Tiles"
    },
    {
      "x": -46,
      "y": 7,
      "z": -8,
      "name": "Lightmetal_Base"
    },
    {
      "x": -46,
      "y": 8,
      "z": -8,
      "name": "Lightmetal_Vertical"
    },
    {
      "x": -46,
      "y": 9,
      "z": -8,
      "name": "Lightmetal_Top"
    },
    {
      "x": -46,
      "y": 10,
      "z": -8,
      "name": "Lightmetal_Base"
    },
    {
      "x": -46,
      "y": 11,
      "z": -8,
      "name": "Lightmetal_Vertical"
    },
    {
      "x": -46,
      "y": 12,
      "z": -8,
      "name": "Lightmetal_Vertical"
    },
    {
      "x": -46,
      "y": 13,
      "z": -8,
      "name": "Pipe_Shell"
    },
    {
      "x": -46,
      "y": 14,
      "z": -8,
      "name": "Pipe_Shell"
    },
    {
      "x": -46,
      "y": 15,
      "z": -8,
      "name": "Pipe_Shell"
    },
    {
      "x": -46,
      "y": 16,
      "z": -8,
      "name": "Cloth_Block_Wool_Blue"
    },
    {
      "x": -46,
      "y": 0,
      "z": -7,
      "name": "Cloth_Block_Wool_Blue"
    },
    {
      "x": -46,
      "y": 6,
      "z": -7,
      "name": "Light_Tiles"
    },
    {
      "x": -46,
      "y": 7,
      "z": -7,
      "name": "Lightmetal_Base"
    },
    {
      "x": -46,
      "y": 8,
      "z": -7,
      "name": "Lightmetal_Vertical"
    },
    {
      "x": -46,
      "y": 9,
      "z": -7,
      "name": "Lightmetal_Top"
    },
    {
      "x": -46,
      "y": 10,
      "z": -7,
      "name": "Lightmetal_Base"
    },
    {
      "x": -46,
      "y": 11,
      "z": -7,
      "name": "Lightmetal_Vertical"
    },
    {
      "x": -46,
      "y": 12,
      "z": -7,
      "name": "Lightmetal_Vertical"
    },
    {
      "x": -46,
      "y": 13,
      "z": -7,
      "name": "Pipe_Shell"
    },
    {
      "x": -46,
      "y": 14,
      "z": -7,
      "name": "Pipe_Shell"
    },
    {
      "x": -46,
      "y": 15,
      "z": -7,
      "name": "Pipe_Shell"
    },
    {
      "x": -46,
      "y": 16,
      "z": -7,
      "name": "Cloth_Block_Wool_Blue"
    },
    {
      "x": -46,
      "y": 0,
      "z": -6,
      "name": "Cloth_Block_Wool_Blue"
    },
    {
      "x": -46,
      "y": 6,
      "z": -6,
      "name": "Light_Tiles"
    },
    {
      "x": -46,
      "y": 7,
      "z": -6,
      "name": "Lightmetal_Base"
    },
    {
      "x": -46,
      "y": 8,
      "z": -6,
      "name": "Lightmetal_Vertical"
    },
    {
      "x": -46,
      "y": 9,
      "z": -6,
      "name": "Lightmetal_Top"
    },
    {
      "x": -46,
      "y": 10,
      "z": -6,
      "name": "Lightmetal_Base"
    },
    {
      "x": -46,
      "y": 11,
      "z": -6,
      "name": "Lightmetal_Vertical"
    },
    {
      "x": -46,
      "y": 12,
      "z": -6,
      "name": "Lightmetal_Vertical"
    },
    {
      "x": -46,
      "y": 13,
      "z": -6,
      "name": "Pipe_Shell"
    },
    {
      "x": -46,
      "y": 14,
      "z": -6,
      "name": "Pipe_Shell"
    },
    {
      "x": -46,
      "y": 15,
      "z": -6,
      "name": "Pipe_Shell"
    },
    {
      "x": -46,
      "y": 16,
      "z": -6,
      "name": "Cloth_Block_Wool_Blue"
    },
    {
      "x": -46,
      "y": 0,
      "z": -5,
      "name": "Cloth_Block_Wool_Blue"
    },
    {
      "x": -46,
      "y": 6,
      "z": -5,
      "name": "Light_Tiles"
    },
    {
      "x": -46,
      "y": 7,
      "z": -5,
      "name": "Lightmetal_Base"
    },
    {
      "x": -46,
      "y": 8,
      "z": -5,
      "name": "Lightmetal_Vertical"
    },
    {
      "x": -46,
      "y": 9,
      "z": -5,
      "name": "Lightmetal_Top"
    },
    {
      "x": -46,
      "y": 10,
      "z": -5,
      "name": "Lightmetal_Base"
    },
    {
      "x": -46,
      "y": 11,
      "z": -5,
      "name": "Lightmetal_Vertical"
    },
    {
      "x": -46,
      "y": 12,
      "z": -5,
      "name": "Lightmetal_Vertical"
    },
    {
      "x": -46,
      "y": 13,
      "z": -5,
      "name": "Pipe_Shell"
    },
    {
      "x": -46,
      "y": 14,
      "z": -5,
      "name": "Pipe_Shell"
    },
    {
      "x": -46,
      "y": 15,
      "z": -5,
      "name": "Pipe_Shell"
    },
    {
      "x": -46,
      "y": 16,
      "z": -5,
      "name": "Cloth_Block_Wool_Blue"
    },
    {
      "x": -46,
      "y": 0,
      "z": -4,
      "name": "Cloth_Block_Wool_Blue"
    },
    {
      "x": -46,
      "y": 6,
      "z": -4,
      "name": "Light_Tiles"
    },
    {
      "x": -46,
      "y": 7,
      "z": -4,
      "name": "Lightmetal_Base"
    },
    {
      "x": -46,
      "y": 8,
      "z": -4,
      "name": "Lightmetal_Vertical"
    },
    {
      "x": -46,
      "y": 9,
      "z": -4,
      "name": "Lightmetal_Top"
    },
    {
      "x": -46,
      "y": 10,
      "z": -4,
      "name": "Lightmetal_Base"
    },
    {
      "x": -46,
      "y": 11,
      "z": -4,
      "name": "Lightmetal_Vertical"
    },
    {
      "x": -46,
      "y": 12,
      "z": -4,
      "name": "Lightmetal_Vertical"
    },
    {
      "x": -46,
      "y": 13,
      "z": -4,
      "name": "Pipe_Shell"
    },
    {
      "x": -46,
      "y": 14,
      "z": -4,
      "name": "Pipe_Shell"
    },
    {
      "x": -46,
      "y": 15,
      "z": -4,
      "name": "Pipe_Shell"
    },
    {
      "x": -46,
      "y": 16,
      "z": -4,
      "name": "Cloth_Block_Wool_Blue"
    },
    {
      "x": -46,
      "y": 0,
      "z": -3,
      "name": "Cloth_Block_Wool_Blue"
    },
    {
      "x": -46,
      "y": 6,
      "z": -3,
      "name": "Light_Tiles"
    },
    {
      "x": -46,
      "y": 7,
      "z": -3,
      "name": "Lightmetal_Base"
    },
    {
      "x": -46,
      "y": 8,
      "z": -3,
      "name": "Lightmetal_Vertical"
    },
    {
      "x": -46,
      "y": 9,
      "z": -3,
      "name": "Lightmetal_Top"
    },
    {
      "x": -46,
      "y": 10,
      "z": -3,
      "name": "Lightmetal_Base"
    },
    {
      "x": -46,
      "y": 11,
      "z": -3,
      "name": "Lightmetal_Vertical"
    },
    {
      "x": -46,
      "y": 12,
      "z": -3,
      "name": "Lightmetal_Vertical"
    },
    {
      "x": -46,
      "y": 13,
      "z": -3,
      "name": "Pipe_Shell"
    },
    {
      "x": -46,
      "y": 14,
      "z": -3,
      "name": "Pipe_Shell"
    },
    {
      "x": -46,
      "y": 15,
      "z": -3,
      "name": "Pipe_Shell"
    },
    {
      "x": -46,
      "y": 16,
      "z": -3,
      "name": "Cloth_Block_Wool_Blue"
    },
    {
      "x": -46,
      "y": 0,
      "z": -2,
      "name": "Cloth_Block_Wool_Blue"
    },
    {
      "x": -46,
      "y": 6,
      "z": -2,
      "name": "Light_Tiles"
    },
    {
      "x": -46,
      "y": 7,
      "z": -2,
      "name": "Lightmetal_Base"
    },
    {
      "x": -46,
      "y": 8,
      "z": -2,
      "name": "Lightmetal_Vertical"
    },
    {
      "x": -46,
      "y": 9,
      "z": -2,
      "name": "Lightmetal_Top"
    },
    {
      "x": -46,
      "y": 10,
      "z": -2,
      "name": "Lightmetal_Base"
    },
    {
      "x": -46,
      "y": 11,
      "z": -2,
      "name": "Lightmetal_Vertical"
    },
    {
      "x": -46,
      "y": 12,
      "z": -2,
      "name": "Lightmetal_Vertical"
    },
    {
      "x": -46,
      "y": 13,
      "z": -2,
      "name": "Pipe_Shell"
    },
    {
      "x": -46,
      "y": 14,
      "z": -2,
      "name": "Pipe_Shell"
    },
    {
      "x": -46,
      "y": 15,
      "z": -2,
      "name": "Pipe_Shell"
    },
    {
      "x": -46,
      "y": 16,
      "z": -2,
      "name": "Cloth_Block_Wool_Blue"
    },
    {
      "x": -46,
      "y": 0,
      "z": -1,
      "name": "Cloth_Block_Wool_Blue"
    },
    {
      "x": -46,
      "y": 6,
      "z": -1,
      "name": "Light_Tiles"
    },
    {
      "x": -46,
      "y": 7,
      "z": -1,
      "name": "Lightmetal_Base"
    },
    {
      "x": -46,
      "y": 8,
      "z": -1,
      "name": "Lightmetal_Vertical"
    },
    {
      "x": -46,
      "y": 9,
      "z": -1,
      "name": "Lightmetal_Top"
    },
    {
      "x": -46,
      "y": 10,
      "z": -1,
      "name": "Lightmetal_Base"
    },
    {
      "x": -46,
      "y": 11,
      "z": -1,
      "name": "Lightmetal_Vertical"
    },
    {
      "x": -46,
      "y": 12,
      "z": -1,
      "name": "Lightmetal_Vertical"
    },
    {
      "x": -46,
      "y": 13,
      "z": -1,
      "name": "Pipe_Shell"
    },
    {
      "x": -46,
      "y": 14,
      "z": -1,
      "name": "Pipe_Shell"
    },
    {
      "x": -46,
      "y": 15,
      "z": -1,
      "name": "Pipe_Shell"
    },
    {
      "x": -46,
      "y": 16,
      "z": -1,
      "name": "Cloth_Block_Wool_Blue"
    },
    {
      "x": -46,
      "y": 0,
      "z": 0,
      "name": "Cloth_Block_Wool_Blue"
    },
    {
      "x": -46,
      "y": 6,
      "z": 0,
      "name": "Light_Tiles"
    },
    {
      "x": -46,
      "y": 7,
      "z": 0,
      "name": "Lightmetal_Base"
    },
    {
      "x": -46,
      "y": 8,
      "z": 0,
      "name": "Lightmetal_Vertical"
    },
    {
      "x": -46,
      "y": 9,
      "z": 0,
      "name": "Lightmetal_Top"
    },
    {
      "x": -46,
      "y": 10,
      "z": 0,
      "name": "Lightmetal_Base"
    },
    {
      "x": -46,
      "y": 11,
      "z": 0,
      "name": "Lightmetal_Vertical"
    },
    {
      "x": -46,
      "y": 12,
      "z": 0,
      "name": "Pipe_Shell"
    },
    {
      "x": -46,
      "y": 13,
      "z": 0,
      "name": "Pipe_Shell"
    },
    {
      "x": -46,
      "y": 14,
      "z": 0,
      "name": "Pipe_Shell"
    },
    {
      "x": -46,
      "y": 15,
      "z": 0,
      "name": "Pipe_Shell"
    },
    {
      "x": -46,
      "y": 16,
      "z": 0,
      "name": "Cloth_Block_Wool_Blue"
    },
    {
      "x": -46,
      "y": 0,
      "z": 1,
      "name": "Cloth_Block_Wool_Blue"
    },
    {
      "x": -46,
      "y": 6,
      "z": 1,
      "name": "Light_Tiles"
    },
    {
      "x": -46,
      "y": 7,
      "z": 1,
      "name": "Lightmetal_Base"
    },
    {
      "x": -46,
      "y": 8,
      "z": 1,
      "name": "Lightmetal_Vertical"
    },
    {
      "x": -46,
      "y": 9,
      "z": 1,
      "name": "Lightmetal_Top"
    },
    {
      "x": -46,
      "y": 10,
      "z": 1,
      "name": "Lightmetal_Base"
    },
    {
      "x": -46,
      "y": 11,
      "z": 1,
      "name": "Lightmetal_Vertical"
    },
    {
      "x": -46,
      "y": 12,
      "z": 1,
      "name": "Pipe_Shell"
    },
    {
      "x": -46,
      "y": 16,
      "z": 1,
      "name": "Pipe_Shell"
    },
    {
      "x": -46,
      "y": 0,
      "z": 2,
      "name": "Cloth_Block_Wool_Blue"
    },
    {
      "x": -46,
      "y": 6,
      "z": 2,
      "name": "Light_Tiles"
    },
    {
      "x": -46,
      "y": 7,
      "z": 2,
      "name": "Lightmetal_Base"
    },
    {
      "x": -46,
      "y": 8,
      "z": 2,
      "name": "Lightmetal_Vertical"
    },
    {
      "x": -46,
      "y": 9,
      "z": 2,
      "name": "Lightmetal_Top"
    },
    {
      "x": -46,
      "y": 10,
      "z": 2,
      "name": "Lightmetal_Base"
    },
    {
      "x": -46,
      "y": 11,
      "z": 2,
      "name": "Lightmetal_Vertical"
    },
    {
      "x": -46,
      "y": 12,
      "z": 2,
      "name": "Pipe_Shell"
    },
    {
      "x": -46,
      "y": 16,
      "z": 2,
      "name": "Pipe_Shell"
    },
    {
      "x": -46,
      "y": 0,
      "z": 3,
      "name": "Cloth_Block_Wool_Blue"
    },
    {
      "x": -46,
      "y": 6,
      "z": 3,
      "name": "Light_Tiles"
    },
    {
      "x": -46,
      "y": 7,
      "z": 3,
      "name": "Lightmetal_Base"
    },
    {
      "x": -46,
      "y": 8,
      "z": 3,
      "name": "Lightmetal_Vertical"
    },
    {
      "x": -46,
      "y": 9,
      "z": 3,
      "name": "Lightmetal_Top"
    },
    {
      "x": -46,
      "y": 10,
      "z": 3,
      "name": "Lightmetal_Base"
    },
    {
      "x": -46,
      "y": 11,
      "z": 3,
      "name": "Lightmetal_Vertical"
    },
    {
      "x": -46,
      "y": 12,
      "z": 3,
      "name": "Pipe_Shell"
    },
    {
      "x": -46,
      "y": 16,
      "z": 3,
      "name": "Pipe_Shell"
    },
    {
      "x": -46,
      "y": 0,
      "z": 4,
      "name": "Cloth_Block_Wool_Blue"
    },
    {
      "x": -46,
      "y": 6,
      "z": 4,
      "name": "Light_Tiles"
    },
    {
      "x": -46,
      "y": 7,
      "z": 4,
      "name": "Lightmetal_Base"
    },
    {
      "x": -46,
      "y": 8,
      "z": 4,
      "name": "Lightmetal_Vertical"
    },
    {
      "x": -46,
      "y": 9,
      "z": 4,
      "name": "Lightmetal_Top"
    },
    {
      "x": -46,
      "y": 10,
      "z": 4,
      "name": "Lightmetal_Base"
    },
    {
      "x": -46,
      "y": 11,
      "z": 4,
      "name": "Lightmetal_Vertical"
    },
    {
      "x": -46,
      "y": 12,
      "z": 4,
      "name": "Pipe_Shell"
    },
    {
      "x": -46,
      "y": 13,
      "z": 4,
      "name": "Pipe_Shell"
    },
    {
      "x": -46,
      "y": 14,
      "z": 4,
      "name": "Pipe_Shell"
    },
    {
      "x": -46,
      "y": 15,
      "z": 4,
      "name": "Pipe_Shell"
    },
    {
      "x": -46,
      "y": 16,
      "z": 4,
      "name": "Pipe_Shell"
    },
    {
      "x": -46,
      "y": 0,
      "z": 5,
      "name": "Cloth_Block_Wool_Blue"
    },
    {
      "x": -46,
      "y": 6,
      "z": 5,
      "name": "Light_Tiles"
    },
    {
      "x": -46,
      "y": 7,
      "z": 5,
      "name": "Lightmetal_Base"
    },
    {
      "x": -46,
      "y": 8,
      "z": 5,
      "name": "Lightmetal_Vertical"
    },
    {
      "x": -46,
      "y": 9,
      "z": 5,
      "name": "Lightmetal_Top"
    },
    {
      "x": -46,
      "y": 10,
      "z": 5,
      "name": "Lightmetal_Base"
    },
    {
      "x": -46,
      "y": 11,
      "z": 5,
      "name": "Lightmetal_Vertical"
    },
    {
      "x": -46,
      "y": 12,
      "z": 5,
      "name": "Lightmetal_Vertical"
    },
    {
      "x": -46,
      "y": 13,
      "z": 5,
      "name": "Pipe_Shell"
    },
    {
      "x": -46,
      "y": 14,
      "z": 5,
      "name": "Pipe_Shell"
    },
    {
      "x": -46,
      "y": 15,
      "z": 5,
      "name": "Pipe_Shell"
    },
    {
      "x": -46,
      "y": 16,
      "z": 5,
      "name": "Cloth_Block_Wool_Blue"
    },
    {
      "x": -46,
      "y": 0,
      "z": 6,
      "name": "Cloth_Block_Wool_Blue"
    },
    {
      "x": -46,
      "y": 6,
      "z": 6,
      "name": "Light_Tiles"
    },
    {
      "x": -46,
      "y": 7,
      "z": 6,
      "name": "Lightmetal_Base"
    },
    {
      "x": -46,
      "y": 8,
      "z": 6,
      "name": "Lightmetal_Vertical"
    },
    {
      "x": -46,
      "y": 9,
      "z": 6,
      "name": "Lightmetal_Top"
    },
    {
      "x": -46,
      "y": 10,
      "z": 6,
      "name": "Lightmetal_Base"
    },
    {
      "x": -46,
      "y": 11,
      "z": 6,
      "name": "Lightmetal_Vertical"
    },
    {
      "x": -46,
      "y": 12,
      "z": 6,
      "name": "Lightmetal_Vertical"
    },
    {
      "x": -46,
      "y": 13,
      "z": 6,
      "name": "Pipe_Shell"
    },
    {
      "x": -46,
      "y": 14,
      "z": 6,
      "name": "Pipe_Shell"
    },
    {
      "x": -46,
      "y": 15,
      "z": 6,
      "name": "Pipe_Shell"
    },
    {
      "x": -46,
      "y": 16,
      "z": 6,
      "name": "Cloth_Block_Wool_Blue"
    },
    {
      "x": -46,
      "y": 0,
      "z": 7,
      "name": "Cloth_Block_Wool_Blue"
    },
    {
      "x": -46,
      "y": 6,
      "z": 7,
      "name": "Light_Tiles"
    },
    {
      "x": -46,
      "y": 7,
      "z": 7,
      "name": "Lightmetal_Base"
    },
    {
      "x": -46,
      "y": 8,
      "z": 7,
      "name": "Lightmetal_Vertical"
    },
    {
      "x": -46,
      "y": 9,
      "z": 7,
      "name": "Lightmetal_Top"
    },
    {
      "x": -46,
      "y": 10,
      "z": 7,
      "name": "Lightmetal_Base"
    },
    {
      "x": -46,
      "y": 11,
      "z": 7,
      "name": "Lightmetal_Vertical"
    },
    {
      "x": -46,
      "y": 12,
      "z": 7,
      "name": "Lightmetal_Vertical"
    },
    {
      "x": -46,
      "y": 13,
      "z": 7,
      "name": "Pipe_Shell"
    },
    {
      "x": -46,
      "y": 14,
      "z": 7,
      "name": "Pipe_Shell"
    },
    {
      "x": -46,
      "y": 15,
      "z": 7,
      "name": "Pipe_Shell"
    },
    {
      "x": -46,
      "y": 16,
      "z": 7,
      "name": "Cloth_Block_Wool_Blue"
    },
    {
      "x": -46,
      "y": 0,
      "z": 8,
      "name": "Cloth_Block_Wool_Blue"
    },
    {
      "x": -46,
      "y": 6,
      "z": 8,
      "name": "Light_Tiles"
    },
    {
      "x": -46,
      "y": 7,
      "z": 8,
      "name": "Lightmetal_Base"
    },
    {
      "x": -46,
      "y": 8,
      "z": 8,
      "name": "Lightmetal_Vertical"
    },
    {
      "x": -46,
      "y": 9,
      "z": 8,
      "name": "Lightmetal_Top"
    },
    {
      "x": -46,
      "y": 10,
      "z": 8,
      "name": "Lightmetal_Base"
    },
    {
      "x": -46,
      "y": 11,
      "z": 8,
      "name": "Lightmetal_Vertical"
    },
    {
      "x": -46,
      "y": 12,
      "z": 8,
      "name": "Lightmetal_Vertical"
    },
    {
      "x": -46,
      "y": 13,
      "z": 8,
      "name": "Pipe_Shell"
    },
    {
      "x": -46,
      "y": 14,
      "z": 8,
      "name": "Pipe_Shell"
    },
    {
      "x": -46,
      "y": 15,
      "z": 8,
      "name": "Pipe_Shell"
    },
    {
      "x": -46,
      "y": 16,
      "z": 8,
      "name": "Cloth_Block_Wool_Blue"
    },
    {
      "x": -46,
      "y": 0,
      "z": 9,
      "name": "Cloth_Block_Wool_Blue"
    },
    {
      "x": -46,
      "y": 6,
      "z": 9,
      "name": "Light_Tiles"
    },
    {
      "x": -46,
      "y": 7,
      "z": 9,
      "name": "Lightmetal_Base"
    },
    {
      "x": -46,
      "y": 8,
      "z": 9,
      "name": "Lightmetal_Vertical"
    },
    {
      "x": -46,
      "y": 9,
      "z": 9,
      "name": "Lightmetal_Top"
    },
    {
      "x": -46,
      "y": 10,
      "z": 9,
      "name": "Lightmetal_Base"
    },
    {
      "x": -46,
      "y": 11,
      "z": 9,
      "name": "Lightmetal_Vertical"
    },
    {
      "x": -46,
      "y": 12,
      "z": 9,
      "name": "Lightmetal_Vertical"
    },
    {
      "x": -46,
      "y": 13,
      "z": 9,
      "name": "Pipe_Shell"
    },
    {
      "x": -46,
      "y": 14,
      "z": 9,
      "name": "Pipe_Shell"
    },
    {
      "x": -46,
      "y": 15,
      "z": 9,
      "name": "Pipe_Shell"
    },
    {
      "x": -46,
      "y": 16,
      "z": 9,
      "name": "Cloth_Block_Wool_Blue"
    },
    {
      "x": -46,
      "y": 0,
      "z": 10,
      "name": "Cloth_Block_Wool_Blue"
    },
    {
      "x": -46,
      "y": 6,
      "z": 10,
      "name": "Light_Tiles"
    },
    {
      "x": -46,
      "y": 7,
      "z": 10,
      "name": "Lightmetal_Base"
    },
    {
      "x": -46,
      "y": 8,
      "z": 10,
      "name": "Lightmetal_Vertical"
    },
    {
      "x": -46,
      "y": 9,
      "z": 10,
      "name": "Lightmetal_Top"
    },
    {
      "x": -46,
      "y": 10,
      "z": 10,
      "name": "Lightmetal_Base"
    },
    {
      "x": -46,
      "y": 11,
      "z": 10,
      "name": "Lightmetal_Vertical"
    },
    {
      "x": -46,
      "y": 12,
      "z": 10,
      "name": "Lightmetal_Vertical"
    },
    {
      "x": -46,
      "y": 13,
      "z": 10,
      "name": "Pipe_Shell"
    },
    {
      "x": -46,
      "y": 14,
      "z": 10,
      "name": "Pipe_Shell"
    },
    {
      "x": -46,
      "y": 15,
      "z": 10,
      "name": "Pipe_Shell"
    },
    {
      "x": -46,
      "y": 16,
      "z": 10,
      "name": "Cloth_Block_Wool_Blue"
    },
    {
      "x": -46,
      "y": 0,
      "z": 11,
      "name": "Cloth_Block_Wool_Blue"
    },
    {
      "x": -46,
      "y": 6,
      "z": 11,
      "name": "Light_Tiles"
    },
    {
      "x": -46,
      "y": 7,
      "z": 11,
      "name": "Lightmetal_Base"
    },
    {
      "x": -46,
      "y": 8,
      "z": 11,
      "name": "Lightmetal_Vertical"
    },
    {
      "x": -46,
      "y": 9,
      "z": 11,
      "name": "Lightmetal_Top"
    },
    {
      "x": -46,
      "y": 10,
      "z": 11,
      "name": "Lightmetal_Base"
    },
    {
      "x": -46,
      "y": 11,
      "z": 11,
      "name": "Lightmetal_Vertical"
    },
    {
      "x": -46,
      "y": 12,
      "z": 11,
      "name": "Lightmetal_Vertical"
    },
    {
      "x": -46,
      "y": 13,
      "z": 11,
      "name": "Pipe_Shell"
    },
    {
      "x": -46,
      "y": 14,
      "z": 11,
      "name": "Pipe_Shell"
    },
    {
      "x": -46,
      "y": 15,
      "z": 11,
      "name": "Pipe_Shell"
    },
    {
      "x": -46,
      "y": 16,
      "z": 11,
      "name": "Cloth_Block_Wool_Blue"
    },
    {
      "x": -46,
      "y": 0,
      "z": 12,
      "name": "Cloth_Block_Wool_Blue"
    },
    {
      "x": -46,
      "y": 6,
      "z": 12,
      "name": "Light_Tiles"
    },
    {
      "x": -46,
      "y": 7,
      "z": 12,
      "name": "Lightmetal_Base"
    },
    {
      "x": -46,
      "y": 8,
      "z": 12,
      "name": "Lightmetal_Vertical"
    },
    {
      "x": -46,
      "y": 9,
      "z": 12,
      "name": "Lightmetal_Top"
    },
    {
      "x": -46,
      "y": 10,
      "z": 12,
      "name": "Lightmetal_Base"
    },
    {
      "x": -46,
      "y": 11,
      "z": 12,
      "name": "Lightmetal_Vertical"
    },
    {
      "x": -46,
      "y": 12,
      "z": 12,
      "name": "Lightmetal_Vertical"
    },
    {
      "x": -46,
      "y": 13,
      "z": 12,
      "name": "Pipe_Shell"
    },
    {
      "x": -46,
      "y": 14,
      "z": 12,
      "name": "Pipe_Shell"
    },
    {
      "x": -46,
      "y": 15,
      "z": 12,
      "name": "Pipe_Shell"
    },
    {
      "x": -46,
      "y": 16,
      "z": 12,
      "name": "Cloth_Block_Wool_Blue"
    },
    {
      "x": -46,
      "y": 0,
      "z": 13,
      "name": "Cloth_Block_Wool_Blue"
    },
    {
      "x": -46,
      "y": 6,
      "z": 13,
      "name": "Light_Tiles"
    },
    {
      "x": -46,
      "y": 7,
      "z": 13,
      "name": "Lightmetal_Base"
    },
    {
      "x": -46,
      "y": 8,
      "z": 13,
      "name": "Lightmetal_Vertical"
    },
    {
      "x": -46,
      "y": 9,
      "z": 13,
      "name": "Lightmetal_Top"
    },
    {
      "x": -46,
      "y": 10,
      "z": 13,
      "name": "Lightmetal_Base"
    },
    {
      "x": -46,
      "y": 11,
      "z": 13,
      "name": "Lightmetal_Vertical"
    },
    {
      "x": -46,
      "y": 12,
      "z": 13,
      "name": "Lightmetal_Vertical"
    },
    {
      "x": -46,
      "y": 13,
      "z": 13,
      "name": "Pipe_Shell"
    },
    {
      "x": -46,
      "y": 14,
      "z": 13,
      "name": "Pipe_Shell"
    },
    {
      "x": -46,
      "y": 15,
      "z": 13,
      "name": "Pipe_Shell"
    },
    {
      "x": -46,
      "y": 16,
      "z": 13,
      "name": "Cloth_Block_Wool_Blue"
    },
    {
      "x": -46,
      "y": 0,
      "z": 14,
      "name": "Cloth_Block_Wool_Blue"
    },
    {
      "x": -46,
      "y": 1,
      "z": 14,
      "name": "Cloth_Block_Wool_Blue"
    },
    {
      "x": -46,
      "y": 2,
      "z": 14,
      "name": "Cloth_Block_Wool_Blue"
    },
    {
      "x": -46,
      "y": 3,
      "z": 14,
      "name": "Cloth_Block_Wool_Blue"
    },
    {
      "x": -46,
      "y": 4,
      "z": 14,
      "name": "Cloth_Block_Wool_Blue"
    },
    {
      "x": -46,
      "y": 5,
      "z": 14,
      "name": "Cloth_Block_Wool_Blue"
    },
    {
      "x": -46,
      "y": 6,
      "z": 14,
      "name": "Light_Tiles"
    },
    {
      "x": -46,
      "y": 7,
      "z": 14,
      "name": "Cloth_Block_Wool_Blue"
    },
    {
      "x": -46,
      "y": 8,
      "z": 14,
      "name": "Cloth_Block_Wool_Blue"
    },
    {
      "x": -46,
      "y": 9,
      "z": 14,
      "name": "Cloth_Block_Wool_Blue"
    },
    {
      "x": -46,
      "y": 10,
      "z": 14,
      "name": "Cloth_Block_Wool_Blue"
    },
    {
      "x": -46,
      "y": 11,
      "z": 14,
      "name": "Cloth_Block_Wool_Blue"
    },
    {
      "x": -46,
      "y": 12,
      "z": 14,
      "name": "Cloth_Block_Wool_Blue"
    },
    {
      "x": -46,
      "y": 13,
      "z": 14,
      "name": "Cloth_Block_Wool_Blue"
    },
    {
      "x": -46,
      "y": 14,
      "z": 14,
      "name": "Cloth_Block_Wool_Blue"
    },
    {
      "x": -46,
      "y": 15,
      "z": 14,
      "name": "Cloth_Block_Wool_Blue"
    },
    {
      "x": -46,
      "y": 16,
      "z": 14,
      "name": "Cloth_Block_Wool_Blue"
    },
    {
      "x": -45,
      "y": 0,
      "z": -10,
      "name": "Cloth_Block_Wool_Blue"
    },
    {
      "x": -45,
      "y": 6,
      "z": -10,
      "name": "Lightmetal_Vertical"
    },
    {
      "x": -45,
      "y": 7,
      "z": -10,
      "name": "Lightmetal_Base"
    },
    {
      "x": -45,
      "y": 8,
      "z": -10,
      "name": "Lightmetal_Vertical"
    },
    {
      "x": -45,
      "y": 9,
      "z": -10,
      "name": "Lightmetal_Top"
    },
    {
      "x": -45,
      "y": 10,
      "z": -10,
      "name": "Lightmetal_Base"
    },
    {
      "x": -45,
      "y": 11,
      "z": -10,
      "name": "Lightmetal_Vertical"
    },
    {
      "x": -45,
      "y": 12,
      "z": -10,
      "name": "Lightmetal_Vertical"
    },
    {
      "x": -45,
      "y": 13,
      "z": -10,
      "name": "Pipe_Shell"
    },
    {
      "x": -45,
      "y": 14,
      "z": -10,
      "name": "Pipe_Shell"
    },
    {
      "x": -45,
      "y": 15,
      "z": -10,
      "name": "Pipe_Shell"
    },
    {
      "x": -45,
      "y": 16,
      "z": -10,
      "name": "Cloth_Block_Wool_Blue"
    },
    {
      "x": -45,
      "y": 6,
      "z": -9,
      "name": "Light_Tiles"
    },
    {
      "x": -45,
      "y": 7,
      "z": -9,
      "name": "Darkmetal_Vertical"
    },
    {
      "x": -45,
      "y": 8,
      "z": -9,
      "name": "Darkmetal_Junction"
    },
    {
      "x": -45,
      "y": 9,
      "z": -9,
      "name": "Darkmetal_Vertical"
    },
    {
      "x": -45,
      "y": 10,
      "z": -9,
      "name": "Darkmetal_Vertical"
    },
    {
      "x": -45,
      "y": 11,
      "z": -9,
      "name": "Darkmetal_Vertical"
    },
    {
      "x": -45,
      "y": 12,
      "z": -9,
      "name": "Pipe_Shell"
    },
    {
      "x": -45,
      "y": 16,
      "z": -9,
      "name": "Pipe_Shell"
    },
    {
      "x": -45,
      "y": 6,
      "z": -8,
      "name": "Light_Tiles"
    },
    {
      "x": -45,
      "y": 7,
      "z": -8,
      "name": "Darkmetal_Vertical"
    },
    {
      "x": -45,
      "y": 8,
      "z": -8,
      "name": "Darkmetal_Junction"
    },
    {
      "x": -45,
      "y": 9,
      "z": -8,
      "name": "Darkmetal_Vertical"
    },
    {
      "x": -45,
      "y": 10,
      "z": -8,
      "name": "Darkmetal_Vertical"
    },
    {
      "x": -45,
      "y": 11,
      "z": -8,
      "name": "Darkmetal_Vertical"
    },
    {
      "x": -45,
      "y": 12,
      "z": -8,
      "name": "Pipe_Shell"
    },
    {
      "x": -45,
      "y": 16,
      "z": -8,
      "name": "Pipe_Shell"
    },
    {
      "x": -45,
      "y": 6,
      "z": -7,
      "name": "Light_Tiles"
    },
    {
      "x": -45,
      "y": 12,
      "z": -7,
      "name": "Pipe_Shell"
    },
    {
      "x": -45,
      "y": 16,
      "z": -7,
      "name": "Pipe_Shell"
    },
    {
      "x": -45,
      "y": 6,
      "z": -6,
      "name": "Light_Tiles"
    },
    {
      "x": -45,
      "y": 12,
      "z": -6,
      "name": "Pipe_Shell"
    },
    {
      "x": -45,
      "y": 16,
      "z": -6,
      "name": "Pipe_Shell"
    },
    {
      "x": -45,
      "y": 6,
      "z": -5,
      "name": "Light_Tiles"
    },
    {
      "x": -45,
      "y": 7,
      "z": -5,
      "name": "Darkmetal_Vertical"
    },
    {
      "x": -45,
      "y": 8,
      "z": -5,
      "name": "Darkmetal_Junction"
    },
    {
      "x": -45,
      "y": 9,
      "z": -5,
      "name": "Darkmetal_Vertical"
    },
    {
      "x": -45,
      "y": 10,
      "z": -5,
      "name": "Darkmetal_Vertical"
    },
    {
      "x": -45,
      "y": 11,
      "z": -5,
      "name": "Darkmetal_Vertical"
    },
    {
      "x": -45,
      "y": 12,
      "z": -5,
      "name": "Pipe_Shell"
    },
    {
      "x": -45,
      "y": 16,
      "z": -5,
      "name": "Pipe_Shell"
    },
    {
      "x": -45,
      "y": 6,
      "z": -4,
      "name": "Light_Tiles"
    },
    {
      "x": -45,
      "y": 12,
      "z": -4,
      "name": "Pipe_Shell"
    },
    {
      "x": -45,
      "y": 16,
      "z": -4,
      "name": "Pipe_Shell"
    },
    {
      "x": -45,
      "y": 6,
      "z": -3,
      "name": "Light_Tiles"
    },
    {
      "x": -45,
      "y": 12,
      "z": -3,
      "name": "Pipe_Shell"
    },
    {
      "x": -45,
      "y": 16,
      "z": -3,
      "name": "Pipe_Shell"
    },
    {
      "x": -45,
      "y": 6,
      "z": -2,
      "name": "Light_Tiles"
    },
    {
      "x": -45,
      "y": 7,
      "z": -2,
      "name": "Darkmetal_Vertical"
    },
    {
      "x": -45,
      "y": 8,
      "z": -2,
      "name": "Darkmetal_Junction"
    },
    {
      "x": -45,
      "y": 9,
      "z": -2,
      "name": "Darkmetal_Vertical"
    },
    {
      "x": -45,
      "y": 10,
      "z": -2,
      "name": "Darkmetal_Vertical"
    },
    {
      "x": -45,
      "y": 11,
      "z": -2,
      "name": "Darkmetal_Junction"
    },
    {
      "x": -45,
      "y": 12,
      "z": -2,
      "name": "Pipe_Shell"
    },
    {
      "x": -45,
      "y": 16,
      "z": -2,
      "name": "Pipe_Shell"
    },
    {
      "x": -45,
      "y": 6,
      "z": -1,
      "name": "Light_Tiles"
    },
    {
      "x": -45,
      "y": 7,
      "z": -1,
      "name": "Lightmetal_Base"
    },
    {
      "x": -45,
      "y": 8,
      "z": -1,
      "name": "Lightmetal_Vertical"
    },
    {
      "x": -45,
      "y": 9,
      "z": -1,
      "name": "Lightmetal_Top"
    },
    {
      "x": -45,
      "y": 10,
      "z": -1,
      "name": "Lightmetal_Base"
    },
    {
      "x": -45,
      "y": 11,
      "z": -1,
      "name": "Lightmetal_Vertical"
    },
    {
      "x": -45,
      "y": 12,
      "z": -1,
      "name": "Pipe_Shell"
    },
    {
      "x": -45,
      "y": 16,
      "z": -1,
      "name": "Pipe_Shell"
    },
    {
      "x": -45,
      "y": 6,
      "z": 0,
      "name": "Light_Tiles"
    },
    {
      "x": -45,
      "y": 11,
      "z": 0,
      "name": "Machine_Light_Lantern"
    },
    {
      "x": -45,
      "y": 12,
      "z": 0,
      "name": "Pipe_Shell"
    },
    {
      "x": -45,
      "y": 16,
      "z": 0,
      "name": "Pipe_Shell"
    },
    {
      "x": -45,
      "y": 6,
      "z": 1,
      "name": "Light_Tiles"
    },
    {
      "x": -45,
      "y": 12,
      "z": 1,
      "name": "Pipe_Shell"
    },
    {
      "x": -45,
      "y": 16,
      "z": 1,
      "name": "Pipe_Shell"
    },
    {
      "x": -45,
      "y": 6,
      "z": 2,
      "name": "Light_Tiles"
    },
    {
      "x": -45,
      "y": 10,
      "z": 2,
      "name": "Plant_Vine",
      "support": 15,
      "rotation": 1
    },
    {
      "x": -45,
      "y": 11,
      "z": 2,
      "name": "Plant_Vine",
      "support": 15,
      "rotation": 1
    },
    {
      "x": -45,
      "y": 12,
      "z": 2,
      "name": "Pipe_Shell"
    },
    {
      "x": -45,
      "y": 16,
      "z": 2,
      "name": "Pipe_Shell"
    },
    {
      "x": -45,
      "y": 6,
      "z": 3,
      "name": "Light_Tiles"
    },
    {
      "x": -45,
      "y": 11,
      "z": 3,
      "name": "Plant_Vine",
      "support": 15,
      "rotation": 1
    },
    {
      "x": -45,
      "y": 12,
      "z": 3,
      "name": "Pipe_Shell"
    },
    {
      "x": -45,
      "y": 16,
      "z": 3,
      "name": "Pipe_Shell"
    },
    {
      "x": -45,
      "y": 6,
      "z": 4,
      "name": "Light_Tiles"
    },
    {
      "x": -45,
      "y": 11,
      "z": 4,
      "name": "Machine_Light_Lantern"
    },
    {
      "x": -45,
      "y": 12,
      "z": 4,
      "name": "Pipe_Shell"
    },
    {
      "x": -45,
      "y": 16,
      "z": 4,
      "name": "Pipe_Shell"
    },
    {
      "x": -45,
      "y": 6,
      "z": 5,
      "name": "Light_Tiles"
    },
    {
      "x": -45,
      "y": 7,
      "z": 5,
      "name": "Lightmetal_Base"
    },
    {
      "x": -45,
      "y": 8,
      "z": 5,
      "name": "Lightmetal_Vertical"
    },
    {
      "x": -45,
      "y": 9,
      "z": 5,
      "name": "Lightmetal_Top"
    },
    {
      "x": -45,
      "y": 10,
      "z": 5,
      "name": "Lightmetal_Base"
    },
    {
      "x": -45,
      "y": 11,
      "z": 5,
      "name": "Lightmetal_Vertical"
    },
    {
      "x": -45,
      "y": 12,
      "z": 5,
      "name": "Pipe_Shell"
    },
    {
      "x": -45,
      "y": 16,
      "z": 5,
      "name": "Pipe_Shell"
    },
    {
      "x": -45,
      "y": 6,
      "z": 6,
      "name": "Light_Tiles"
    },
    {
      "x": -45,
      "y": 7,
      "z": 6,
      "name": "Darkmetal_Vertical"
    },
    {
      "x": -45,
      "y": 8,
      "z": 6,
      "name": "Darkmetal_Junction"
    },
    {
      "x": -45,
      "y": 9,
      "z": 6,
      "name": "Darkmetal_Vertical"
    },
    {
      "x": -45,
      "y": 10,
      "z": 6,
      "name": "Darkmetal_Vertical"
    },
    {
      "x": -45,
      "y": 11,
      "z": 6,
      "name": "Darkmetal_Junction"
    },
    {
      "x": -45,
      "y": 12,
      "z": 6,
      "name": "Pipe_Shell"
    },
    {
      "x": -45,
      "y": 16,
      "z": 6,
      "name": "Pipe_Shell"
    },
    {
      "x": -45,
      "y": 6,
      "z": 7,
      "name": "Light_Tiles"
    },
    {
      "x": -45,
      "y": 12,
      "z": 7,
      "name": "Pipe_Shell"
    },
    {
      "x": -45,
      "y": 16,
      "z": 7,
      "name": "Pipe_Shell"
    },
    {
      "x": -45,
      "y": 6,
      "z": 8,
      "name": "Light_Tiles"
    },
    {
      "x": -45,
      "y": 12,
      "z": 8,
      "name": "Pipe_Shell"
    },
    {
      "x": -45,
      "y": 16,
      "z": 8,
      "name": "Pipe_Shell"
    },
    {
      "x": -45,
      "y": 6,
      "z": 9,
      "name": "Light_Tiles"
    },
    {
      "x": -45,
      "y": 7,
      "z": 9,
      "name": "Darkmetal_Vertical"
    },
    {
      "x": -45,
      "y": 8,
      "z": 9,
      "name": "Darkmetal_Junction"
    },
    {
      "x": -45,
      "y": 9,
      "z": 9,
      "name": "Darkmetal_Vertical"
    },
    {
      "x": -45,
      "y": 10,
      "z": 9,
      "name": "Darkmetal_Vertical"
    },
    {
      "x": -45,
      "y": 11,
      "z": 9,
      "name": "Darkmetal_Vertical"
    },
    {
      "x": -45,
      "y": 12,
      "z": 9,
      "name": "Pipe_Shell"
    },
    {
      "x": -45,
      "y": 16,
      "z": 9,
      "name": "Pipe_Shell"
    },
    {
      "x": -45,
      "y": 6,
      "z": 10,
      "name": "Light_Tiles"
    },
    {
      "x": -45,
      "y": 12,
      "z": 10,
      "name": "Pipe_Shell"
    },
    {
      "x": -45,
      "y": 16,
      "z": 10,
      "name": "Pipe_Shell"
    },
    {
      "x": -45,
      "y": 6,
      "z": 11,
      "name": "Light_Tiles"
    },
    {
      "x": -45,
      "y": 12,
      "z": 11,
      "name": "Pipe_Shell"
    },
    {
      "x": -45,
      "y": 16,
      "z": 11,
      "name": "Pipe_Shell"
    },
    {
      "x": -45,
      "y": 6,
      "z": 12,
      "name": "Light_Tiles"
    },
    {
      "x": -45,
      "y": 7,
      "z": 12,
      "name": "Darkmetal_Vertical"
    },
    {
      "x": -45,
      "y": 8,
      "z": 12,
      "name": "Darkmetal_Junction"
    },
    {
      "x": -45,
      "y": 9,
      "z": 12,
      "name": "Darkmetal_Vertical"
    },
    {
      "x": -45,
      "y": 10,
      "z": 12,
      "name": "Darkmetal_Vertical"
    },
    {
      "x": -45,
      "y": 11,
      "z": 12,
      "name": "Darkmetal_Vertical"
    },
    {
      "x": -45,
      "y": 12,
      "z": 12,
      "name": "Pipe_Shell"
    },
    {
      "x": -45,
      "y": 16,
      "z": 12,
      "name": "Pipe_Shell"
    },
    {
      "x": -45,
      "y": 6,
      "z": 13,
      "name": "Light_Tiles"
    },
    {
      "x": -45,
      "y": 7,
      "z": 13,
      "name": "Darkmetal_Vertical"
    },
    {
      "x": -45,
      "y": 8,
      "z": 13,
      "name": "Darkmetal_Vertical"
    },
    {
      "x": -45,
      "y": 9,
      "z": 13,
      "name": "Darkmetal_Vertical"
    },
    {
      "x": -45,
      "y": 10,
      "z": 13,
      "name": "Darkmetal_Vertical"
    },
    {
      "x": -45,
      "y": 11,
      "z": 13,
      "name": "Darkmetal_Vertical"
    },
    {
      "x": -45,
      "y": 12,
      "z": 13,
      "name": "Pipe_Shell"
    },
    {
      "x": -45,
      "y": 16,
      "z": 13,
      "name": "Pipe_Shell"
    },
    {
      "x": -45,
      "y": 0,
      "z": 14,
      "name": "Cloth_Block_Wool_Blue"
    },
    {
      "x": -45,
      "y": 6,
      "z": 14,
      "name": "Light_Tiles"
    },
    {
      "x": -45,
      "y": 7,
      "z": 14,
      "name": "Lightmetal_Base"
    },
    {
      "x": -45,
      "y": 8,
      "z": 14,
      "name": "Lightmetal_Vertical"
    },
    {
      "x": -45,
      "y": 9,
      "z": 14,
      "name": "Lightmetal_Top"
    },
    {
      "x": -45,
      "y": 10,
      "z": 14,
      "name": "Lightmetal_Base"
    },
    {
      "x": -45,
      "y": 11,
      "z": 14,
      "name": "Lightmetal_Vertical"
    },
    {
      "x": -45,
      "y": 12,
      "z": 14,
      "name": "Lightmetal_Vertical"
    },
    {
      "x": -45,
      "y": 13,
      "z": 14,
      "name": "Pipe_Shell"
    },
    {
      "x": -45,
      "y": 14,
      "z": 14,
      "name": "Pipe_Shell"
    },
    {
      "x": -45,
      "y": 15,
      "z": 14,
      "name": "Pipe_Shell"
    },
    {
      "x": -45,
      "y": 16,
      "z": 14,
      "name": "Cloth_Block_Wool_Blue"
    },
    {
      "x": -44,
      "y": 0,
      "z": -10,
      "name": "Cloth_Block_Wool_Blue"
    },
    {
      "x": -44,
      "y": 6,
      "z": -10,
      "name": "Lightmetal_Vertical"
    },
    {
      "x": -44,
      "y": 7,
      "z": -10,
      "name": "Lightmetal_Base"
    },
    {
      "x": -44,
      "y": 8,
      "z": -10,
      "name": "Lightmetal_Vertical"
    },
    {
      "x": -44,
      "y": 9,
      "z": -10,
      "name": "Lightmetal_Top"
    },
    {
      "x": -44,
      "y": 10,
      "z": -10,
      "name": "Lightmetal_Base"
    },
    {
      "x": -44,
      "y": 11,
      "z": -10,
      "name": "Lightmetal_Vertical"
    },
    {
      "x": -44,
      "y": 12,
      "z": -10,
      "name": "Lightmetal_Vertical"
    },
    {
      "x": -44,
      "y": 13,
      "z": -10,
      "name": "Pipe_Shell"
    },
    {
      "x": -44,
      "y": 14,
      "z": -10,
      "name": "Pipe_Shell"
    },
    {
      "x": -44,
      "y": 15,
      "z": -10,
      "name": "Pipe_Shell"
    },
    {
      "x": -44,
      "y": 16,
      "z": -10,
      "name": "Cloth_Block_Wool_Blue"
    },
    {
      "x": -44,
      "y": 6,
      "z": -9,
      "name": "Light_Tiles"
    },
    {
      "x": -44,
      "y": 7,
      "z": -9,
      "name": "Darkmetal_Vertical"
    },
    {
      "x": -44,
      "y": 8,
      "z": -9,
      "name": "Darkmetal_Junction"
    },
    {
      "x": -44,
      "y": 9,
      "z": -9,
      "name": "Darkmetal_Vertical"
    },
    {
      "x": -44,
      "y": 10,
      "z": -9,
      "name": "Darkmetal_Vertical"
    },
    {
      "x": -44,
      "y": 11,
      "z": -9,
      "name": "Darkmetal_Vertical"
    },
    {
      "x": -44,
      "y": 12,
      "z": -9,
      "name": "Pipe_Shell"
    },
    {
      "x": -44,
      "y": 16,
      "z": -9,
      "name": "Pipe_Shell"
    },
    {
      "x": -44,
      "y": 6,
      "z": -8,
      "name": "Light_Tiles"
    },
    {
      "x": -44,
      "y": 7,
      "z": -8,
      "name": "Darkmetal_Vertical"
    },
    {
      "x": -44,
      "y": 8,
      "z": -8,
      "name": "Darkmetal_Junction"
    },
    {
      "x": -44,
      "y": 9,
      "z": -8,
      "name": "Darkmetal_Vertical"
    },
    {
      "x": -44,
      "y": 10,
      "z": -8,
      "name": "Darkmetal_Vertical"
    },
    {
      "x": -44,
      "y": 11,
      "z": -8,
      "name": "Darkmetal_Vertical"
    },
    {
      "x": -44,
      "y": 12,
      "z": -8,
      "name": "Pipe_Shell"
    },
    {
      "x": -44,
      "y": 16,
      "z": -8,
      "name": "Pipe_Shell"
    },
    {
      "x": -44,
      "y": 6,
      "z": -7,
      "name": "Light_Tiles"
    },
    {
      "x": -44,
      "y": 12,
      "z": -7,
      "name": "Pipe_Shell"
    },
    {
      "x": -44,
      "y": 16,
      "z": -7,
      "name": "Pipe_Shell"
    },
    {
      "x": -44,
      "y": 6,
      "z": -6,
      "name": "Light_Tiles"
    },
    {
      "x": -44,
      "y": 12,
      "z": -6,
      "name": "Pipe_Shell"
    },
    {
      "x": -44,
      "y": 16,
      "z": -6,
      "name": "Pipe_Shell"
    },
    {
      "x": -44,
      "y": 6,
      "z": -5,
      "name": "Light_Tiles"
    },
    {
      "x": -44,
      "y": 11,
      "z": -5,
      "name": "Machine_Light_Lantern"
    },
    {
      "x": -44,
      "y": 12,
      "z": -5,
      "name": "Pipe_Shell"
    },
    {
      "x": -44,
      "y": 16,
      "z": -5,
      "name": "Pipe_Shell"
    },
    {
      "x": -44,
      "y": 6,
      "z": -4,
      "name": "Light_Tiles"
    },
    {
      "x": -44,
      "y": 12,
      "z": -4,
      "name": "Pipe_Shell"
    },
    {
      "x": -44,
      "y": 16,
      "z": -4,
      "name": "Pipe_Shell"
    },
    {
      "x": -44,
      "y": 6,
      "z": -3,
      "name": "Light_Tiles"
    },
    {
      "x": -44,
      "y": 12,
      "z": -3,
      "name": "Pipe_Shell"
    },
    {
      "x": -44,
      "y": 16,
      "z": -3,
      "name": "Pipe_Shell"
    },
    {
      "x": -44,
      "y": 6,
      "z": -2,
      "name": "Light_Tiles"
    },
    {
      "x": -44,
      "y": 11,
      "z": -2,
      "name": "Darkmetal_Horizontal",
      "rotation": 1
    },
    {
      "x": -44,
      "y": 12,
      "z": -2,
      "name": "Pipe_Shell"
    },
    {
      "x": -44,
      "y": 16,
      "z": -2,
      "name": "Pipe_Shell"
    },
    {
      "x": -44,
      "y": 6,
      "z": -1,
      "name": "Light_Tiles"
    },
    {
      "x": -44,
      "y": 7,
      "z": -1,
      "name": "Lightmetal_Base"
    },
    {
      "x": -44,
      "y": 8,
      "z": -1,
      "name": "Lightmetal_Vertical"
    },
    {
      "x": -44,
      "y": 9,
      "z": -1,
      "name": "Lightmetal_Top"
    },
    {
      "x": -44,
      "y": 10,
      "z": -1,
      "name": "Lightmetal_Base"
    },
    {
      "x": -44,
      "y": 11,
      "z": -1,
      "name": "Lightmetal_Vertical"
    },
    {
      "x": -44,
      "y": 12,
      "z": -1,
      "name": "Pipe_Shell"
    },
    {
      "x": -44,
      "y": 16,
      "z": -1,
      "name": "Pipe_Shell"
    },
    {
      "x": -44,
      "y": 6,
      "z": 0,
      "name": "Light_Tiles"
    },
    {
      "x": -44,
      "y": 12,
      "z": 0,
      "name": "Pipe_Shell"
    },
    {
      "x": -44,
      "y": 16,
      "z": 0,
      "name": "Pipe_Shell"
    },
    {
      "x": -44,
      "y": 6,
      "z": 1,
      "name": "Floor_Tiles_Horizontal"
    },
    {
      "x": -44,
      "y": 12,
      "z": 1,
      "name": "Pipe_Shell"
    },
    {
      "x": -44,
      "y": 16,
      "z": 1,
      "name": "Pipe_Shell"
    },
    {
      "x": -44,
      "y": 6,
      "z": 2,
      "name": "Floor_Tiles_Horizontal"
    },
    {
      "x": -44,
      "y": 12,
      "z": 2,
      "name": "Pipe_Shell"
    },
    {
      "x": -44,
      "y": 16,
      "z": 2,
      "name": "Pipe_Shell"
    },
    {
      "x": -44,
      "y": 6,
      "z": 3,
      "name": "Floor_Tiles_Horizontal"
    },
    {
      "x": -44,
      "y": 12,
      "z": 3,
      "name": "Pipe_Shell"
    },
    {
      "x": -44,
      "y": 16,
      "z": 3,
      "name": "Pipe_Shell"
    },
    {
      "x": -44,
      "y": 6,
      "z": 4,
      "name": "Light_Tiles"
    },
    {
      "x": -44,
      "y": 9,
      "z": 4,
      "name": "Plant_Vine",
      "support": 15,
      "rotation": 2
    },
    {
      "x": -44,
      "y": 10,
      "z": 4,
      "name": "Plant_Vine",
      "support": 15,
      "rotation": 2
    },
    {
      "x": -44,
      "y": 11,
      "z": 4,
      "name": "Plant_Vine",
      "support": 15,
      "rotation": 2
    },
    {
      "x": -44,
      "y": 12,
      "z": 4,
      "name": "Pipe_Shell"
    },
    {
      "x": -44,
      "y": 16,
      "z": 4,
      "name": "Pipe_Shell"
    },
    {
      "x": -44,
      "y": 6,
      "z": 5,
      "name": "Light_Tiles"
    },
    {
      "x": -44,
      "y": 7,
      "z": 5,
      "name": "Lightmetal_Base"
    },
    {
      "x": -44,
      "y": 8,
      "z": 5,
      "name": "Lightmetal_Vertical"
    },
    {
      "x": -44,
      "y": 9,
      "z": 5,
      "name": "Lightmetal_Top"
    },
    {
      "x": -44,
      "y": 10,
      "z": 5,
      "name": "Lightmetal_Base"
    },
    {
      "x": -44,
      "y": 11,
      "z": 5,
      "name": "Lightmetal_Vertical"
    },
    {
      "x": -44,
      "y": 12,
      "z": 5,
      "name": "Pipe_Shell"
    },
    {
      "x": -44,
      "y": 16,
      "z": 5,
      "name": "Pipe_Shell"
    },
    {
      "x": -44,
      "y": 6,
      "z": 6,
      "name": "Light_Tiles"
    },
    {
      "x": -44,
      "y": 11,
      "z": 6,
      "name": "Darkmetal_Horizontal",
      "rotation": 1
    },
    {
      "x": -44,
      "y": 12,
      "z": 6,
      "name": "Pipe_Shell"
    },
    {
      "x": -44,
      "y": 16,
      "z": 6,
      "name": "Pipe_Shell"
    },
    {
      "x": -44,
      "y": 6,
      "z": 7,
      "name": "Light_Tiles"
    },
    {
      "x": -44,
      "y": 12,
      "z": 7,
      "name": "Pipe_Shell"
    },
    {
      "x": -44,
      "y": 16,
      "z": 7,
      "name": "Pipe_Shell"
    },
    {
      "x": -44,
      "y": 6,
      "z": 8,
      "name": "Light_Tiles"
    },
    {
      "x": -44,
      "y": 12,
      "z": 8,
      "name": "Pipe_Shell"
    },
    {
      "x": -44,
      "y": 16,
      "z": 8,
      "name": "Pipe_Shell"
    },
    {
      "x": -44,
      "y": 6,
      "z": 9,
      "name": "Light_Tiles"
    },
    {
      "x": -44,
      "y": 11,
      "z": 9,
      "name": "Machine_Light_Lantern"
    },
    {
      "x": -44,
      "y": 12,
      "z": 9,
      "name": "Pipe_Shell"
    },
    {
      "x": -44,
      "y": 16,
      "z": 9,
      "name": "Pipe_Shell"
    },
    {
      "x": -44,
      "y": 6,
      "z": 10,
      "name": "Light_Tiles"
    },
    {
      "x": -44,
      "y": 12,
      "z": 10,
      "name": "Pipe_Shell"
    },
    {
      "x": -44,
      "y": 16,
      "z": 10,
      "name": "Pipe_Shell"
    },
    {
      "x": -44,
      "y": 6,
      "z": 11,
      "name": "Light_Tiles"
    },
    {
      "x": -44,
      "y": 12,
      "z": 11,
      "name": "Pipe_Shell"
    },
    {
      "x": -44,
      "y": 16,
      "z": 11,
      "name": "Pipe_Shell"
    },
    {
      "x": -44,
      "y": 6,
      "z": 12,
      "name": "Light_Tiles"
    },
    {
      "x": -44,
      "y": 7,
      "z": 12,
      "name": "Darkmetal_Vertical"
    },
    {
      "x": -44,
      "y": 8,
      "z": 12,
      "name": "Darkmetal_Junction"
    },
    {
      "x": -44,
      "y": 9,
      "z": 12,
      "name": "Darkmetal_Vertical"
    },
    {
      "x": -44,
      "y": 10,
      "z": 12,
      "name": "Darkmetal_Vertical"
    },
    {
      "x": -44,
      "y": 11,
      "z": 12,
      "name": "Darkmetal_Vertical"
    },
    {
      "x": -44,
      "y": 12,
      "z": 12,
      "name": "Pipe_Shell"
    },
    {
      "x": -44,
      "y": 16,
      "z": 12,
      "name": "Pipe_Shell"
    },
    {
      "x": -44,
      "y": 6,
      "z": 13,
      "name": "Light_Tiles"
    },
    {
      "x": -44,
      "y": 7,
      "z": 13,
      "name": "Darkmetal_Vertical"
    },
    {
      "x": -44,
      "y": 8,
      "z": 13,
      "name": "Darkmetal_Junction"
    },
    {
      "x": -44,
      "y": 9,
      "z": 13,
      "name": "Darkmetal_Vertical"
    },
    {
      "x": -44,
      "y": 10,
      "z": 13,
      "name": "Darkmetal_Vertical"
    },
    {
      "x": -44,
      "y": 11,
      "z": 13,
      "name": "Darkmetal_Vertical"
    },
    {
      "x": -44,
      "y": 12,
      "z": 13,
      "name": "Pipe_Shell"
    },
    {
      "x": -44,
      "y": 16,
      "z": 13,
      "name": "Pipe_Shell"
    },
    {
      "x": -44,
      "y": 0,
      "z": 14,
      "name": "Cloth_Block_Wool_Blue"
    },
    {
      "x": -44,
      "y": 6,
      "z": 14,
      "name": "Light_Tiles"
    },
    {
      "x": -44,
      "y": 7,
      "z": 14,
      "name": "Lightmetal_Base"
    },
    {
      "x": -44,
      "y": 8,
      "z": 14,
      "name": "Lightmetal_Vertical"
    },
    {
      "x": -44,
      "y": 9,
      "z": 14,
      "name": "Lightmetal_Top"
    },
    {
      "x": -44,
      "y": 10,
      "z": 14,
      "name": "Lightmetal_Base"
    },
    {
      "x": -44,
      "y": 11,
      "z": 14,
      "name": "Lightmetal_Vertical"
    },
    {
      "x": -44,
      "y": 12,
      "z": 14,
      "name": "Lightmetal_Vertical"
    },
    {
      "x": -44,
      "y": 13,
      "z": 14,
      "name": "Pipe_Shell"
    },
    {
      "x": -44,
      "y": 14,
      "z": 14,
      "name": "Pipe_Shell"
    },
    {
      "x": -44,
      "y": 15,
      "z": 14,
      "name": "Pipe_Shell"
    },
    {
      "x": -44,
      "y": 16,
      "z": 14,
      "name": "Cloth_Block_Wool_Blue"
    },
    {
      "x": -43,
      "y": 0,
      "z": -10,
      "name": "Cloth_Block_Wool_Blue"
    },
    {
      "x": -43,
      "y": 6,
      "z": -10,
      "name": "Lightmetal_Vertical"
    },
    {
      "x": -43,
      "y": 7,
      "z": -10,
      "name": "Lightmetal_Base"
    },
    {
      "x": -43,
      "y": 8,
      "z": -10,
      "name": "Lightmetal_Vertical"
    },
    {
      "x": -43,
      "y": 9,
      "z": -10,
      "name": "Lightmetal_Top"
    },
    {
      "x": -43,
      "y": 10,
      "z": -10,
      "name": "Lightmetal_Base"
    },
    {
      "x": -43,
      "y": 11,
      "z": -10,
      "name": "Lightmetal_Vertical"
    },
    {
      "x": -43,
      "y": 12,
      "z": -10,
      "name": "Lightmetal_Vertical"
    },
    {
      "x": -43,
      "y": 13,
      "z": -10,
      "name": "Pipe_Shell"
    },
    {
      "x": -43,
      "y": 14,
      "z": -10,
      "name": "Pipe_Shell"
    },
    {
      "x": -43,
      "y": 15,
      "z": -10,
      "name": "Pipe_Shell"
    },
    {
      "x": -43,
      "y": 16,
      "z": -10,
      "name": "Cloth_Block_Wool_Blue"
    },
    {
      "x": -43,
      "y": 6,
      "z": -9,
      "name": "Light_Tiles"
    },
    {
      "x": -43,
      "y": 12,
      "z": -9,
      "name": "Pipe_Shell"
    },
    {
      "x": -43,
      "y": 16,
      "z": -9,
      "name": "Pipe_Shell"
    },
    {
      "x": -43,
      "y": 6,
      "z": -8,
      "name": "Light_Tiles"
    },
    {
      "x": -43,
      "y": 12,
      "z": -8,
      "name": "Pipe_Shell"
    },
    {
      "x": -43,
      "y": 16,
      "z": -8,
      "name": "Pipe_Shell"
    },
    {
      "x": -43,
      "y": 6,
      "z": -7,
      "name": "Light_Tiles"
    },
    {
      "x": -43,
      "y": 12,
      "z": -7,
      "name": "Pipe_Shell"
    },
    {
      "x": -43,
      "y": 16,
      "z": -7,
      "name": "Pipe_Shell"
    },
    {
      "x": -43,
      "y": 6,
      "z": -6,
      "name": "Light_Tiles"
    },
    {
      "x": -43,
      "y": 12,
      "z": -6,
      "name": "Pipe_Shell"
    },
    {
      "x": -43,
      "y": 16,
      "z": -6,
      "name": "Pipe_Shell"
    },
    {
      "x": -43,
      "y": 6,
      "z": -5,
      "name": "Light_Tiles"
    },
    {
      "x": -43,
      "y": 12,
      "z": -5,
      "name": "Pipe_Shell"
    },
    {
      "x": -43,
      "y": 16,
      "z": -5,
      "name": "Pipe_Shell"
    },
    {
      "x": -43,
      "y": 6,
      "z": -4,
      "name": "Light_Tiles"
    },
    {
      "x": -43,
      "y": 12,
      "z": -4,
      "name": "Pipe_Shell"
    },
    {
      "x": -43,
      "y": 16,
      "z": -4,
      "name": "Pipe_Shell"
    },
    {
      "x": -43,
      "y": 6,
      "z": -3,
      "name": "Light_Tiles"
    },
    {
      "x": -43,
      "y": 12,
      "z": -3,
      "name": "Pipe_Shell"
    },
    {
      "x": -43,
      "y": 16,
      "z": -3,
      "name": "Pipe_Shell"
    },
    {
      "x": -43,
      "y": 6,
      "z": -2,
      "name": "Light_Tiles"
    },
    {
      "x": -43,
      "y": 11,
      "z": -2,
      "name": "Darkmetal_Horizontal",
      "rotation": 1
    },
    {
      "x": -43,
      "y": 12,
      "z": -2,
      "name": "Pipe_Shell"
    },
    {
      "x": -43,
      "y": 16,
      "z": -2,
      "name": "Pipe_Shell"
    },
    {
      "x": -43,
      "y": 6,
      "z": -1,
      "name": "Light_Tiles"
    },
    {
      "x": -43,
      "y": 7,
      "z": -1,
      "name": "Lightmetal_Base"
    },
    {
      "x": -43,
      "y": 8,
      "z": -1,
      "name": "Lightmetal_Vertical"
    },
    {
      "x": -43,
      "y": 9,
      "z": -1,
      "name": "Lightmetal_Top"
    },
    {
      "x": -43,
      "y": 10,
      "z": -1,
      "name": "Lightmetal_Base"
    },
    {
      "x": -43,
      "y": 11,
      "z": -1,
      "name": "Lightmetal_Vertical"
    },
    {
      "x": -43,
      "y": 12,
      "z": -1,
      "name": "Pipe_Shell"
    },
    {
      "x": -43,
      "y": 16,
      "z": -1,
      "name": "Pipe_Shell"
    },
    {
      "x": -43,
      "y": 6,
      "z": 0,
      "name": "Light_Tiles"
    },
    {
      "x": -43,
      "y": 8,
      "z": 0,
      "name": "Plant_Vine",
      "support": 15
    },
    {
      "x": -43,
      "y": 9,
      "z": 0,
      "name": "Plant_Vine",
      "support": 15
    },
    {
      "x": -43,
      "y": 10,
      "z": 0,
      "name": "Plant_Vine",
      "support": 15
    },
    {
      "x": -43,
      "y": 11,
      "z": 0,
      "name": "Plant_Vine",
      "support": 15
    },
    {
      "x": -43,
      "y": 12,
      "z": 0,
      "name": "Pipe_Shell"
    },
    {
      "x": -43,
      "y": 16,
      "z": 0,
      "name": "Pipe_Shell"
    },
    {
      "x": -43,
      "y": 6,
      "z": 1,
      "name": "Floor_Tiles_Horizontal"
    },
    {
      "x": -43,
      "y": 12,
      "z": 1,
      "name": "Pipe_Shell"
    },
    {
      "x": -43,
      "y": 16,
      "z": 1,
      "name": "Pipe_Shell"
    },
    {
      "x": -43,
      "y": 6,
      "z": 2,
      "name": "Floor_Hex_Tiles"
    },
    {
      "x": -43,
      "y": 12,
      "z": 2,
      "name": "Pipe_Shell"
    },
    {
      "x": -43,
      "y": 16,
      "z": 2,
      "name": "Pipe_Shell"
    },
    {
      "x": -43,
      "y": 6,
      "z": 3,
      "name": "Floor_Tiles_Horizontal"
    },
    {
      "x": -43,
      "y": 12,
      "z": 3,
      "name": "Pipe_Shell"
    },
    {
      "x": -43,
      "y": 16,
      "z": 3,
      "name": "Pipe_Shell"
    },
    {
      "x": -43,
      "y": 6,
      "z": 4,
      "name": "Light_Tiles"
    },
    {
      "x": -43,
      "y": 10,
      "z": 4,
      "name": "Plant_Vine",
      "support": 15,
      "rotation": 2
    },
    {
      "x": -43,
      "y": 11,
      "z": 4,
      "name": "Plant_Vine",
      "support": 15,
      "rotation": 2
    },
    {
      "x": -43,
      "y": 12,
      "z": 4,
      "name": "Pipe_Shell"
    },
    {
      "x": -43,
      "y": 16,
      "z": 4,
      "name": "Pipe_Shell"
    },
    {
      "x": -43,
      "y": 6,
      "z": 5,
      "name": "Light_Tiles"
    },
    {
      "x": -43,
      "y": 7,
      "z": 5,
      "name": "Lightmetal_Base"
    },
    {
      "x": -43,
      "y": 8,
      "z": 5,
      "name": "Lightmetal_Vertical"
    },
    {
      "x": -43,
      "y": 9,
      "z": 5,
      "name": "Lightmetal_Top"
    },
    {
      "x": -43,
      "y": 10,
      "z": 5,
      "name": "Lightmetal_Base"
    },
    {
      "x": -43,
      "y": 11,
      "z": 5,
      "name": "Lightmetal_Vertical"
    },
    {
      "x": -43,
      "y": 12,
      "z": 5,
      "name": "Pipe_Shell"
    },
    {
      "x": -43,
      "y": 16,
      "z": 5,
      "name": "Pipe_Shell"
    },
    {
      "x": -43,
      "y": 6,
      "z": 6,
      "name": "Light_Tiles"
    },
    {
      "x": -43,
      "y": 11,
      "z": 6,
      "name": "Darkmetal_Horizontal",
      "rotation": 1
    },
    {
      "x": -43,
      "y": 12,
      "z": 6,
      "name": "Pipe_Shell"
    },
    {
      "x": -43,
      "y": 16,
      "z": 6,
      "name": "Pipe_Shell"
    },
    {
      "x": -43,
      "y": 6,
      "z": 7,
      "name": "Light_Tiles"
    },
    {
      "x": -43,
      "y": 12,
      "z": 7,
      "name": "Pipe_Shell"
    },
    {
      "x": -43,
      "y": 16,
      "z": 7,
      "name": "Pipe_Shell"
    },
    {
      "x": -43,
      "y": 6,
      "z": 8,
      "name": "Light_Tiles"
    },
    {
      "x": -43,
      "y": 12,
      "z": 8,
      "name": "Pipe_Shell"
    },
    {
      "x": -43,
      "y": 16,
      "z": 8,
      "name": "Pipe_Shell"
    },
    {
      "x": -43,
      "y": 6,
      "z": 9,
      "name": "Light_Tiles"
    },
    {
      "x": -43,
      "y": 12,
      "z": 9,
      "name": "Pipe_Shell"
    },
    {
      "x": -43,
      "y": 16,
      "z": 9,
      "name": "Pipe_Shell"
    },
    {
      "x": -43,
      "y": 6,
      "z": 10,
      "name": "Light_Tiles"
    },
    {
      "x": -43,
      "y": 12,
      "z": 10,
      "name": "Pipe_Shell"
    },
    {
      "x": -43,
      "y": 16,
      "z": 10,
      "name": "Pipe_Shell"
    },
    {
      "x": -43,
      "y": 6,
      "z": 11,
      "name": "Light_Tiles"
    },
    {
      "x": -43,
      "y": 12,
      "z": 11,
      "name": "Pipe_Shell"
    },
    {
      "x": -43,
      "y": 16,
      "z": 11,
      "name": "Pipe_Shell"
    },
    {
      "x": -43,
      "y": 6,
      "z": 12,
      "name": "Light_Tiles"
    },
    {
      "x": -43,
      "y": 12,
      "z": 12,
      "name": "Pipe_Shell"
    },
    {
      "x": -43,
      "y": 16,
      "z": 12,
      "name": "Pipe_Shell"
    },
    {
      "x": -43,
      "y": 6,
      "z": 13,
      "name": "Light_Tiles"
    },
    {
      "x": -43,
      "y": 12,
      "z": 13,
      "name": "Pipe_Shell"
    },
    {
      "x": -43,
      "y": 16,
      "z": 13,
      "name": "Pipe_Shell"
    },
    {
      "x": -43,
      "y": 0,
      "z": 14,
      "name": "Cloth_Block_Wool_Blue"
    },
    {
      "x": -43,
      "y": 6,
      "z": 14,
      "name": "Light_Tiles"
    },
    {
      "x": -43,
      "y": 7,
      "z": 14,
      "name": "Lightmetal_Base"
    },
    {
      "x": -43,
      "y": 8,
      "z": 14,
      "name": "Lightmetal_Vertical"
    },
    {
      "x": -43,
      "y": 9,
      "z": 14,
      "name": "Lightmetal_Top"
    },
    {
      "x": -43,
      "y": 10,
      "z": 14,
      "name": "Lightmetal_Base"
    },
    {
      "x": -43,
      "y": 11,
      "z": 14,
      "name": "Lightmetal_Vertical"
    },
    {
      "x": -43,
      "y": 12,
      "z": 14,
      "name": "Lightmetal_Vertical"
    },
    {
      "x": -43,
      "y": 13,
      "z": 14,
      "name": "Pipe_Shell"
    },
    {
      "x": -43,
      "y": 14,
      "z": 14,
      "name": "Pipe_Shell"
    },
    {
      "x": -43,
      "y": 15,
      "z": 14,
      "name": "Pipe_Shell"
    },
    {
      "x": -43,
      "y": 16,
      "z": 14,
      "name": "Cloth_Block_Wool_Blue"
    },
    {
      "x": -42,
      "y": 0,
      "z": -10,
      "name": "Cloth_Block_Wool_Blue"
    },
    {
      "x": -42,
      "y": 6,
      "z": -10,
      "name": "Lightmetal_Vertical"
    },
    {
      "x": -42,
      "y": 7,
      "z": -10,
      "name": "Lightmetal_Base"
    },
    {
      "x": -42,
      "y": 8,
      "z": -10,
      "name": "Lightmetal_Vertical"
    },
    {
      "x": -42,
      "y": 9,
      "z": -10,
      "name": "Lightmetal_Top"
    },
    {
      "x": -42,
      "y": 10,
      "z": -10,
      "name": "Lightmetal_Base"
    },
    {
      "x": -42,
      "y": 11,
      "z": -10,
      "name": "Lightmetal_Vertical"
    },
    {
      "x": -42,
      "y": 12,
      "z": -10,
      "name": "Lightmetal_Vertical"
    },
    {
      "x": -42,
      "y": 13,
      "z": -10,
      "name": "Pipe_Shell"
    },
    {
      "x": -42,
      "y": 14,
      "z": -10,
      "name": "Pipe_Shell"
    },
    {
      "x": -42,
      "y": 15,
      "z": -10,
      "name": "Pipe_Shell"
    },
    {
      "x": -42,
      "y": 16,
      "z": -10,
      "name": "Cloth_Block_Wool_Blue"
    },
    {
      "x": -42,
      "y": 6,
      "z": -9,
      "name": "Light_Tiles"
    },
    {
      "x": -42,
      "y": 12,
      "z": -9,
      "name": "Pipe_Shell"
    },
    {
      "x": -42,
      "y": 16,
      "z": -9,
      "name": "Pipe_Shell"
    },
    {
      "x": -42,
      "y": 6,
      "z": -8,
      "name": "Light_Tiles"
    },
    {
      "x": -42,
      "y": 12,
      "z": -8,
      "name": "Pipe_Shell"
    },
    {
      "x": -42,
      "y": 16,
      "z": -8,
      "name": "Pipe_Shell"
    },
    {
      "x": -42,
      "y": 6,
      "z": -7,
      "name": "Light_Tiles"
    },
    {
      "x": -42,
      "y": 12,
      "z": -7,
      "name": "Pipe_Shell"
    },
    {
      "x": -42,
      "y": 16,
      "z": -7,
      "name": "Pipe_Shell"
    },
    {
      "x": -42,
      "y": 6,
      "z": -6,
      "name": "Light_Tiles"
    },
    {
      "x": -42,
      "y": 12,
      "z": -6,
      "name": "Pipe_Shell"
    },
    {
      "x": -42,
      "y": 13,
      "z": -6,
      "name": "Pipe_Shell"
    },
    {
      "x": -42,
      "y": 14,
      "z": -6,
      "name": "Pipe_Shell"
    },
    {
      "x": -42,
      "y": 15,
      "z": -6,
      "name": "Pipe_Shell"
    },
    {
      "x": -42,
      "y": 16,
      "z": -6,
      "name": "Darkmetal_Smooth"
    },
    {
      "x": -42,
      "y": 6,
      "z": -5,
      "name": "Light_Tiles"
    },
    {
      "x": -42,
      "y": 12,
      "z": -5,
      "name": "Pipe_Shell"
    },
    {
      "x": -42,
      "y": 13,
      "z": -5,
      "name": "Pipe_Shell"
    },
    {
      "x": -42,
      "y": 14,
      "z": -5,
      "name": "Pipe_Shell"
    },
    {
      "x": -42,
      "y": 15,
      "z": -5,
      "name": "Pipe_Shell"
    },
    {
      "x": -42,
      "y": 16,
      "z": -5,
      "name": "Darkmetal_Smooth"
    },
    {
      "x": -42,
      "y": 6,
      "z": -4,
      "name": "Light_Tiles"
    },
    {
      "x": -42,
      "y": 12,
      "z": -4,
      "name": "Pipe_Shell"
    },
    {
      "x": -42,
      "y": 13,
      "z": -4,
      "name": "Pipe_Shell"
    },
    {
      "x": -42,
      "y": 14,
      "z": -4,
      "name": "Pipe_Shell"
    },
    {
      "x": -42,
      "y": 15,
      "z": -4,
      "name": "Pipe_Shell"
    },
    {
      "x": -42,
      "y": 16,
      "z": -4,
      "name": "Darkmetal_Smooth"
    },
    {
      "x": -42,
      "y": 6,
      "z": -3,
      "name": "Light_Tiles"
    },
    {
      "x": -42,
      "y": 12,
      "z": -3,
      "name": "Pipe_Shell"
    },
    {
      "x": -42,
      "y": 13,
      "z": -3,
      "name": "Pipe_Shell"
    },
    {
      "x": -42,
      "y": 14,
      "z": -3,
      "name": "Pipe_Shell"
    },
    {
      "x": -42,
      "y": 15,
      "z": -3,
      "name": "Pipe_Shell"
    },
    {
      "x": -42,
      "y": 16,
      "z": -3,
      "name": "Darkmetal_Smooth"
    },
    {
      "x": -42,
      "y": 6,
      "z": -2,
      "name": "Light_Tiles"
    },
    {
      "x": -42,
      "y": 11,
      "z": -2,
      "name": "Darkmetal_Horizontal",
      "rotation": 1
    },
    {
      "x": -42,
      "y": 12,
      "z": -2,
      "name": "Lightmetal_Vertical"
    },
    {
      "x": -42,
      "y": 13,
      "z": -2,
      "name": "Pipe_Shell"
    },
    {
      "x": -42,
      "y": 14,
      "z": -2,
      "name": "Pipe_Shell"
    },
    {
      "x": -42,
      "y": 15,
      "z": -2,
      "name": "Pipe_Shell"
    },
    {
      "x": -42,
      "y": 16,
      "z": -2,
      "name": "Darkmetal_Smooth"
    },
    {
      "x": -42,
      "y": 6,
      "z": -1,
      "name": "Light_Tiles"
    },
    {
      "x": -42,
      "y": 7,
      "z": -1,
      "name": "Lightmetal_Base"
    },
    {
      "x": -42,
      "y": 8,
      "z": -1,
      "name": "Lightmetal_Vertical"
    },
    {
      "x": -42,
      "y": 9,
      "z": -1,
      "name": "Lightmetal_Top"
    },
    {
      "x": -42,
      "y": 10,
      "z": -1,
      "name": "Lightmetal_Base"
    },
    {
      "x": -42,
      "y": 11,
      "z": -1,
      "name": "Lightmetal_Vertical"
    },
    {
      "x": -42,
      "y": 12,
      "z": -1,
      "name": "Lightmetal_Vertical"
    },
    {
      "x": -42,
      "y": 13,
      "z": -1,
      "name": "Pipe_Shell"
    },
    {
      "x": -42,
      "y": 14,
      "z": -1,
      "name": "Pipe_Shell"
    },
    {
      "x": -42,
      "y": 15,
      "z": -1,
      "name": "Pipe_Shell"
    },
    {
      "x": -42,
      "y": 16,
      "z": -1,
      "name": "Darkmetal_Smooth"
    },
    {
      "x": -42,
      "y": 6,
      "z": 0,
      "name": "Light_Tiles"
    },
    {
      "x": -42,
      "y": 9,
      "z": 0,
      "name": "Plant_Vine",
      "support": 15
    },
    {
      "x": -42,
      "y": 10,
      "z": 0,
      "name": "Plant_Vine",
      "support": 15
    },
    {
      "x": -42,
      "y": 11,
      "z": 0,
      "name": "Plant_Vine",
      "support": 15
    },
    {
      "x": -42,
      "y": 12,
      "z": 0,
      "name": "Pipe_Shell"
    },
    {
      "x": -42,
      "y": 16,
      "z": 0,
      "name": "Pipe_Shell"
    },
    {
      "x": -42,
      "y": 6,
      "z": 1,
      "name": "Floor_Tiles_Horizontal"
    },
    {
      "x": -42,
      "y": 12,
      "z": 1,
      "name": "Pipe_Shell"
    },
    {
      "x": -42,
      "y": 16,
      "z": 1,
      "name": "Pipe_Shell"
    },
    {
      "x": -42,
      "y": 6,
      "z": 2,
      "name": "Floor_Tiles_Horizontal"
    },
    {
      "x": -42,
      "y": 12,
      "z": 2,
      "name": "Pipe_Shell"
    },
    {
      "x": -42,
      "y": 16,
      "z": 2,
      "name": "Pipe_Shell"
    },
    {
      "x": -42,
      "y": 6,
      "z": 3,
      "name": "Floor_Tiles_Horizontal"
    },
    {
      "x": -42,
      "y": 12,
      "z": 3,
      "name": "Pipe_Shell"
    },
    {
      "x": -42,
      "y": 16,
      "z": 3,
      "name": "Pipe_Shell"
    },
    {
      "x": -42,
      "y": 6,
      "z": 4,
      "name": "Light_Tiles"
    },
    {
      "x": -42,
      "y": 11,
      "z": 4,
      "name": "Plant_Vine",
      "support": 15,
      "rotation": 2
    },
    {
      "x": -42,
      "y": 12,
      "z": 4,
      "name": "Pipe_Shell"
    },
    {
      "x": -42,
      "y": 16,
      "z": 4,
      "name": "Pipe_Shell"
    },
    {
      "x": -42,
      "y": 6,
      "z": 5,
      "name": "Light_Tiles"
    },
    {
      "x": -42,
      "y": 7,
      "z": 5,
      "name": "Lightmetal_Base"
    },
    {
      "x": -42,
      "y": 8,
      "z": 5,
      "name": "Lightmetal_Vertical"
    },
    {
      "x": -42,
      "y": 9,
      "z": 5,
      "name": "Lightmetal_Top"
    },
    {
      "x": -42,
      "y": 10,
      "z": 5,
      "name": "Lightmetal_Base"
    },
    {
      "x": -42,
      "y": 11,
      "z": 5,
      "name": "Lightmetal_Vertical"
    },
    {
      "x": -42,
      "y": 12,
      "z": 5,
      "name": "Pipe_Shell"
    },
    {
      "x": -42,
      "y": 13,
      "z": 5,
      "name": "Pipe_Shell"
    },
    {
      "x": -42,
      "y": 14,
      "z": 5,
      "name": "Pipe_Shell"
    },
    {
      "x": -42,
      "y": 15,
      "z": 5,
      "name": "Pipe_Shell"
    },
    {
      "x": -42,
      "y": 16,
      "z": 5,
      "name": "Darkmetal_Smooth"
    },
    {
      "x": -42,
      "y": 6,
      "z": 6,
      "name": "Light_Tiles"
    },
    {
      "x": -42,
      "y": 11,
      "z": 6,
      "name": "Darkmetal_Horizontal",
      "rotation": 1
    },
    {
      "x": -42,
      "y": 12,
      "z": 6,
      "name": "Pipe_Shell"
    },
    {
      "x": -42,
      "y": 13,
      "z": 6,
      "name": "Pipe_Shell"
    },
    {
      "x": -42,
      "y": 14,
      "z": 6,
      "name": "Pipe_Shell"
    },
    {
      "x": -42,
      "y": 15,
      "z": 6,
      "name": "Pipe_Shell"
    },
    {
      "x": -42,
      "y": 16,
      "z": 6,
      "name": "Darkmetal_Smooth"
    },
    {
      "x": -42,
      "y": 6,
      "z": 7,
      "name": "Light_Tiles"
    },
    {
      "x": -42,
      "y": 12,
      "z": 7,
      "name": "Pipe_Shell"
    },
    {
      "x": -42,
      "y": 13,
      "z": 7,
      "name": "Pipe_Shell"
    },
    {
      "x": -42,
      "y": 14,
      "z": 7,
      "name": "Pipe_Shell"
    },
    {
      "x": -42,
      "y": 15,
      "z": 7,
      "name": "Pipe_Shell"
    },
    {
      "x": -42,
      "y": 16,
      "z": 7,
      "name": "Darkmetal_Smooth"
    },
    {
      "x": -42,
      "y": 6,
      "z": 8,
      "name": "Light_Tiles"
    },
    {
      "x": -42,
      "y": 12,
      "z": 8,
      "name": "Pipe_Shell"
    },
    {
      "x": -42,
      "y": 13,
      "z": 8,
      "name": "Pipe_Shell"
    },
    {
      "x": -42,
      "y": 14,
      "z": 8,
      "name": "Pipe_Shell"
    },
    {
      "x": -42,
      "y": 15,
      "z": 8,
      "name": "Pipe_Shell"
    },
    {
      "x": -42,
      "y": 16,
      "z": 8,
      "name": "Darkmetal_Smooth"
    },
    {
      "x": -42,
      "y": 6,
      "z": 9,
      "name": "Light_Tiles"
    },
    {
      "x": -42,
      "y": 12,
      "z": 9,
      "name": "Pipe_Shell"
    },
    {
      "x": -42,
      "y": 13,
      "z": 9,
      "name": "Pipe_Shell"
    },
    {
      "x": -42,
      "y": 14,
      "z": 9,
      "name": "Pipe_Shell"
    },
    {
      "x": -42,
      "y": 15,
      "z": 9,
      "name": "Pipe_Shell"
    },
    {
      "x": -42,
      "y": 16,
      "z": 9,
      "name": "Darkmetal_Smooth"
    },
    {
      "x": -42,
      "y": 6,
      "z": 10,
      "name": "Light_Tiles"
    },
    {
      "x": -42,
      "y": 12,
      "z": 10,
      "name": "Pipe_Shell"
    },
    {
      "x": -42,
      "y": 13,
      "z": 10,
      "name": "Pipe_Shell"
    },
    {
      "x": -42,
      "y": 14,
      "z": 10,
      "name": "Pipe_Shell"
    },
    {
      "x": -42,
      "y": 15,
      "z": 10,
      "name": "Pipe_Shell"
    },
    {
      "x": -42,
      "y": 16,
      "z": 10,
      "name": "Darkmetal_Smooth"
    },
    {
      "x": -42,
      "y": 6,
      "z": 11,
      "name": "Light_Tiles"
    },
    {
      "x": -42,
      "y": 12,
      "z": 11,
      "name": "Pipe_Shell"
    },
    {
      "x": -42,
      "y": 16,
      "z": 11,
      "name": "Pipe_Shell"
    },
    {
      "x": -42,
      "y": 6,
      "z": 12,
      "name": "Light_Tiles"
    },
    {
      "x": -42,
      "y": 12,
      "z": 12,
      "name": "Pipe_Shell"
    },
    {
      "x": -42,
      "y": 16,
      "z": 12,
      "name": "Pipe_Shell"
    },
    {
      "x": -42,
      "y": 6,
      "z": 13,
      "name": "Light_Tiles"
    },
    {
      "x": -42,
      "y": 12,
      "z": 13,
      "name": "Pipe_Shell"
    },
    {
      "x": -42,
      "y": 16,
      "z": 13,
      "name": "Pipe_Shell"
    },
    {
      "x": -42,
      "y": 0,
      "z": 14,
      "name": "Cloth_Block_Wool_Blue"
    },
    {
      "x": -42,
      "y": 6,
      "z": 14,
      "name": "Light_Tiles"
    },
    {
      "x": -42,
      "y": 7,
      "z": 14,
      "name": "Lightmetal_Base"
    },
    {
      "x": -42,
      "y": 8,
      "z": 14,
      "name": "Lightmetal_Vertical"
    },
    {
      "x": -42,
      "y": 9,
      "z": 14,
      "name": "Lightmetal_Top"
    },
    {
      "x": -42,
      "y": 10,
      "z": 14,
      "name": "Lightmetal_Base"
    },
    {
      "x": -42,
      "y": 11,
      "z": 14,
      "name": "Lightmetal_Vertical"
    },
    {
      "x": -42,
      "y": 12,
      "z": 14,
      "name": "Lightmetal_Vertical"
    },
    {
      "x": -42,
      "y": 13,
      "z": 14,
      "name": "Pipe_Shell"
    },
    {
      "x": -42,
      "y": 14,
      "z": 14,
      "name": "Pipe_Shell"
    },
    {
      "x": -42,
      "y": 15,
      "z": 14,
      "name": "Pipe_Shell"
    },
    {
      "x": -42,
      "y": 16,
      "z": 14,
      "name": "Cloth_Block_Wool_Blue"
    },
    {
      "x": -41,
      "y": 0,
      "z": -10,
      "name": "Cloth_Block_Wool_Blue"
    },
    {
      "x": -41,
      "y": 6,
      "z": -10,
      "name": "Lightmetal_Vertical"
    },
    {
      "x": -41,
      "y": 7,
      "z": -10,
      "name": "Lightmetal_Base"
    },
    {
      "x": -41,
      "y": 8,
      "z": -10,
      "name": "Lightmetal_Vertical"
    },
    {
      "x": -41,
      "y": 9,
      "z": -10,
      "name": "Lightmetal_Top"
    },
    {
      "x": -41,
      "y": 10,
      "z": -10,
      "name": "Lightmetal_Base"
    },
    {
      "x": -41,
      "y": 11,
      "z": -10,
      "name": "Lightmetal_Vertical"
    },
    {
      "x": -41,
      "y": 12,
      "z": -10,
      "name": "Lightmetal_Vertical"
    },
    {
      "x": -41,
      "y": 13,
      "z": -10,
      "name": "Pipe_Shell"
    },
    {
      "x": -41,
      "y": 14,
      "z": -10,
      "name": "Pipe_Shell"
    },
    {
      "x": -41,
      "y": 15,
      "z": -10,
      "name": "Pipe_Shell"
    },
    {
      "x": -41,
      "y": 16,
      "z": -10,
      "name": "Cloth_Block_Wool_Blue"
    },
    {
      "x": -41,
      "y": 6,
      "z": -9,
      "name": "Light_Tiles"
    },
    {
      "x": -41,
      "y": 7,
      "z": -9,
      "name": "Darkmetal_Vertical"
    },
    {
      "x": -41,
      "y": 8,
      "z": -9,
      "name": "Darkmetal_Junction"
    },
    {
      "x": -41,
      "y": 9,
      "z": -9,
      "name": "Darkmetal_Vertical"
    },
    {
      "x": -41,
      "y": 10,
      "z": -9,
      "name": "Darkmetal_Vertical"
    },
    {
      "x": -41,
      "y": 11,
      "z": -9,
      "name": "Darkmetal_Vertical"
    },
    {
      "x": -41,
      "y": 12,
      "z": -9,
      "name": "Pipe_Shell"
    },
    {
      "x": -41,
      "y": 16,
      "z": -9,
      "name": "Pipe_Shell"
    },
    {
      "x": -41,
      "y": 6,
      "z": -8,
      "name": "Light_Tiles"
    },
    {
      "x": -41,
      "y": 11,
      "z": -8,
      "name": "Machine_Light_Lantern"
    },
    {
      "x": -41,
      "y": 12,
      "z": -8,
      "name": "Pipe_Shell"
    },
    {
      "x": -41,
      "y": 16,
      "z": -8,
      "name": "Pipe_Shell"
    },
    {
      "x": -41,
      "y": 6,
      "z": -7,
      "name": "Light_Tiles"
    },
    {
      "x": -41,
      "y": 12,
      "z": -7,
      "name": "Pipe_Shell"
    },
    {
      "x": -41,
      "y": 16,
      "z": -7,
      "name": "Pipe_Shell"
    },
    {
      "x": -41,
      "y": 6,
      "z": -6,
      "name": "Light_Tiles"
    },
    {
      "x": -41,
      "y": 12,
      "z": -6,
      "name": "Pipe_Shell"
    },
    {
      "x": -41,
      "y": 13,
      "z": -6,
      "name": "Pipe_Shell"
    },
    {
      "x": -41,
      "y": 14,
      "z": -6,
      "name": "Pipe_Shell"
    },
    {
      "x": -41,
      "y": 15,
      "z": -6,
      "name": "Pipe_Shell"
    },
    {
      "x": -41,
      "y": 16,
      "z": -6,
      "name": "Darkmetal_Smooth"
    },
    {
      "x": -41,
      "y": 6,
      "z": -5,
      "name": "Light_Tiles"
    },
    {
      "x": -41,
      "y": 16,
      "z": -5,
      "name": "Darkmetal_Smooth"
    },
    {
      "x": -41,
      "y": 6,
      "z": -4,
      "name": "Light_Tiles"
    },
    {
      "x": -41,
      "y": 15,
      "z": -4,
      "name": "Plant_Vine_Wall",
      "support": 15,
      "rotation": 1
    },
    {
      "x": -41,
      "y": 16,
      "z": -4,
      "name": "Darkmetal_Smooth"
    },
    {
      "x": -41,
      "y": 6,
      "z": -3,
      "name": "Light_Tiles"
    },
    {
      "x": -41,
      "y": 13,
      "z": -3,
      "name": "Plant_Vine_Wall",
      "support": 15,
      "rotation": 1
    },
    {
      "x": -41,
      "y": 14,
      "z": -3,
      "name": "Plant_Vine",
      "support": 15,
      "rotation": 1
    },
    {
      "x": -41,
      "y": 15,
      "z": -3,
      "name": "Plant_Vine",
      "support": 15,
      "rotation": 1
    },
    {
      "x": -41,
      "y": 16,
      "z": -3,
      "name": "Darkmetal_Smooth"
    },
    {
      "x": -41,
      "y": 6,
      "z": -2,
      "name": "Light_Tiles"
    },
    {
      "x": -41,
      "y": 10,
      "z": -2,
      "name": "Machine_Light_Lantern"
    },
    {
      "x": -41,
      "y": 11,
      "z": -2,
      "name": "Darkmetal_Junction"
    },
    {
      "x": -41,
      "y": 12,
      "z": -2,
      "name": "Darkmetal_Vertical"
    },
    {
      "x": -41,
      "y": 13,
      "z": -2,
      "name": "Darkmetal_Vertical"
    },
    {
      "x": -41,
      "y": 14,
      "z": -2,
      "name": "Darkmetal_Vertical"
    },
    {
      "x": -41,
      "y": 15,
      "z": -2,
      "name": "Darkmetal_Vertical"
    },
    {
      "x": -41,
      "y": 16,
      "z": -2,
      "name": "Darkmetal_Smooth"
    },
    {
      "x": -41,
      "y": 6,
      "z": -1,
      "name": "Light_Tiles"
    },
    {
      "x": -41,
      "y": 7,
      "z": -1,
      "name": "Lightmetal_Base"
    },
    {
      "x": -41,
      "y": 8,
      "z": -1,
      "name": "Lightmetal_Vertical"
    },
    {
      "x": -41,
      "y": 9,
      "z": -1,
      "name": "Lightmetal_Top"
    },
    {
      "x": -41,
      "y": 10,
      "z": -1,
      "name": "Lightmetal_Base"
    },
    {
      "x": -41,
      "y": 11,
      "z": -1,
